Error fitting recommender: name 'prepare_training_data' is not defined
Error fitting recommender: name 'prepare_training_data' is not defined
Error fitting recommender: name 'prepare_training_data' is not defined
Error fitting recommender: name 'prepare_training_data' is not defined
Error fitting recommender: name 'prepare_training_data' is not defined
Error fitting recommender: name 'prepare_training_data' is not defined
Error fitting recommender: name 'prepare_training_data' is not defined
Error fitting recommender: name 'prepare_training_data' is not defined
Error fitting recommender: HybridRecommender.fit() got an unexpected keyword argument 'user_id'
Error fitting recommender: HybridRecommender.fit() got an unexpected keyword argument 'user_id'
Error fitting recommender: HybridRecommender.fit() got an unexpected keyword argument 'user_id'
Error fitting recommender: HybridRecommender.fit() got an unexpected keyword argument 'user_id'
Error fitting recommender: HybridRecommender.fit() got an unexpected keyword argument 'user_id'
Error fitting recommender: "value" parameter must be a scalar or dict, but you passed a "list"
Error fitting recommender: "value" parameter must be a scalar or dict, but you passed a "list"
Error fitting recommender: "value" parameter must be a scalar or dict, but you passed a "list"
Error fitting recommender: "value" parameter must be a scalar or dict, but you passed a "list"
Error fitting recommender: "value" parameter must be a scalar or dict, but you passed a "list"
Error fitting recommender: "value" parameter must be a scalar or dict, but you passed a "list"
Error fitting recommender: "value" parameter must be a scalar or dict, but you passed a "list"
Error fitting recommender: "value" parameter must be a scalar or dict, but you passed a "list"
Error fitting recommender: HybridRecommender.fit() got an unexpected keyword argument 'user_id'
Error fitting recommender: HybridRecommender.fit() got an unexpected keyword argument 'user_id'
Error fitting recommender: HybridRecommender.fit() got an unexpected keyword argument 'user_id'
Error fitting recommender: HybridRecommender.fit() got an unexpected keyword argument 'user_id'
Error fitting recommender: HybridRecommender.fit() got an unexpected keyword argument 'user_id'
Error fitting recommender: HybridRecommender.fit() got an unexpected keyword argument 'user_id'
Error fitting recommender: HybridRecommender.fit() got an unexpected keyword argument 'user_id'
Error fitting recommender: HybridRecommender.fit() got an unexpected keyword argument 'user_id'
Error fitting recommender: HybridRecommender.fit() got an unexpected keyword argument 'user_id'
Error fitting recommender: HybridRecommender.fit() got an unexpected keyword argument 'user_id'
Error fitting recommender: HybridRecommender.fit() got an unexpected keyword argument 'user_id'
Error fitting recommender: HybridRecommender.fit() got an unexpected keyword argument 'user_id'
Error fitting recommender: HybridRecommender.fit() got an unexpected keyword argument 'user_id'
Error fitting recommender: HybridRecommender.fit() got an unexpected keyword argument 'user_id'
Error fitting recommender: HybridRecommender.fit() got an unexpected keyword argument 'user_id'
Error fitting recommender: HybridRecommender.fit() got an unexpected keyword argument 'user_id'
Error fitting recommender: HybridRecommender.fit() got an unexpected keyword argument 'user_id'
Error fitting recommender: unhashable type: 'list'
Error fitting recommender: unhashable type: 'list'
Error fitting recommender: name 'train_test_split' is not defined
Error fitting recommender: unhashable type: 'list'
Error fitting recommender: unhashable type: 'list'
Error fitting recommender: unhashable type: 'list'
Error fitting recommender: unhashable type: 'list'
Error fitting recommender: unhashable type: 'list'
Error fitting recommender: HybridRecommender.fit() got an unexpected keyword argument 'user_id'
Error fitting recommender: HybridRecommender.fit() got an unexpected keyword argument 'user_id'
Error fitting recommender: HybridRecommender.fit() got an unexpected keyword argument 'user_id'
Error fitting recommender: HybridRecommender.fit() got an unexpected keyword argument 'user_id'
Error fitting recommender: HybridRecommender.fit() got an unexpected keyword argument 'user_id'
Error fitting recommender: HybridRecommender.fit() got an unexpected keyword argument 'user_id'
Error fitting recommender: HybridRecommender.fit() got an unexpected keyword argument 'user_id'
Error fitting recommender: HybridRecommender.fit() got an unexpected keyword argument 'user_id'
Error fitting recommender: HybridRecommender.fit() got an unexpected keyword argument 'user_id'
Error fitting recommender: HybridRecommender.fit() got an unexpected keyword argument 'user_id'
Error fitting recommender: HybridRecommender.fit() got an unexpected keyword argument 'user_id'
Error fitting recommender: HybridRecommender.fit() got an unexpected keyword argument 'user_id'
Error fitting recommender: HybridRecommender.fit() got an unexpected keyword argument 'user_id'
Error fitting recommender: HybridRecommender.fit() got an unexpected keyword argument 'user_id'
Error fitting recommender: HybridRecommender.fit() got an unexpected keyword argument 'user_id'
Error fitting recommender: HybridRecommender.fit() got an unexpected keyword argument 'user_id'
Error fitting recommender: HybridRecommender.fit() got an unexpected keyword argument 'user_id'
Error fitting recommender: HybridRecommender.fit() got an unexpected keyword argument 'user_id'
Error fitting recommender: HybridRecommender.fit() got an unexpected keyword argument 'user_id'
Error fitting recommender: HybridRecommender.fit() got an unexpected keyword argument 'user_id'
Error fitting recommender: HybridRecommender.fit() got an unexpected keyword argument 'user_id'
Error fitting recommender: HybridRecommender.fit() got an unexpected keyword argument 'user_id'
Error fitting recommender: HybridRecommender.fit() got an unexpected keyword argument 'user_id'
Error fitting recommender: HybridRecommender.fit() got an unexpected keyword argument 'user_id'
Error fitting recommender: HybridRecommender.fit() got an unexpected keyword argument 'user_id'
Error fitting recommender: HybridRecommender.fit() got an unexpected keyword argument 'user_id'
Error fitting recommender: HybridRecommender.fit() got an unexpected keyword argument 'user_id'
Error fitting recommender: HybridRecommender.fit() got an unexpected keyword argument 'user_id'
Error fitting recommender: HybridRecommender.fit() got an unexpected keyword argument 'user_id'
Error fitting recommender: HybridRecommender.fit() got an unexpected keyword argument 'user_id'
Error fitting recommender: HybridRecommender.fit() got an unexpected keyword argument 'user_id'
Error fitting recommender: HybridRecommender.fit() got an unexpected keyword argument 'user_id'
Error fitting recommender: HybridRecommender.fit() got an unexpected keyword argument 'user_id'
Error fitting recommender: HybridRecommender.fit() got an unexpected keyword argument 'user_id'
Error fitting recommender: HybridRecommender.fit() got an unexpected keyword argument 'user_id'
Error fitting recommender: HybridRecommender.fit() got an unexpected keyword argument 'user_id'
Error fitting recommender: HybridRecommender.fit() got an unexpected keyword argument 'user_id'
Error fitting recommender: HybridRecommender.fit() got an unexpected keyword argument 'user_id'
Error fitting recommender: HybridRecommender.fit() got an unexpected keyword argument 'user_id'
Error fitting recommender: HybridRecommender.fit() got an unexpected keyword argument 'user_id'
Error fitting recommender: HybridRecommender.fit() got an unexpected keyword argument 'user_id'
Error fitting recommender: HybridRecommender.fit() got an unexpected keyword argument 'user_id'
Error fitting recommender: HybridRecommender.fit() got an unexpected keyword argument 'user_id'
Error fitting recommender: HybridRecommender.fit() got an unexpected keyword argument 'user_id'
Error fitting recommender: HybridRecommender.fit() got an unexpected keyword argument 'user_id'
Error fitting recommender: HybridRecommender.fit() got an unexpected keyword argument 'user_id'
Error fitting recommender: HybridRecommender.fit() got an unexpected keyword argument 'user_id'
Error fitting recommender: HybridRecommender.fit() got an unexpected keyword argument 'user_id'
Error fitting recommender: HybridRecommender.fit() got an unexpected keyword argument 'user_id'
Error fitting recommender: HybridRecommender.fit() got an unexpected keyword argument 'user_id'
Error fitting recommender: HybridRecommender.fit() got an unexpected keyword argument 'user_id'
Error fitting recommender: HybridRecommender.fit() got an unexpected keyword argument 'user_id'
Error fitting recommender: HybridRecommender.fit() got an unexpected keyword argument 'user_id'
Error fitting recommender: HybridRecommender.fit() got an unexpected keyword argument 'user_id'
Error fitting recommender: HybridRecommender.fit() got an unexpected keyword argument 'user_id'
Error fitting recommender: HybridRecommender.fit() got an unexpected keyword argument 'user_id'
Error fitting recommender: HybridRecommender.fit() got an unexpected keyword argument 'user_id'
Error fitting recommender: HybridRecommender.fit() got an unexpected keyword argument 'user_id'
Error fitting recommender: HybridRecommender.fit() got an unexpected keyword argument 'user_id'
Error fitting recommender: HybridRecommender.fit() got an unexpected keyword argument 'user_id'
Error fitting recommender: HybridRecommender.fit() got an unexpected keyword argument 'user_id'
Error fitting recommender: HybridRecommender.fit() got an unexpected keyword argument 'user_id'
Error fitting recommender: HybridRecommender.fit() got an unexpected keyword argument 'user_id'
Error fitting recommender: HybridRecommender.fit() got an unexpected keyword argument 'user_id'
Error fitting recommender: HybridRecommender.fit() got an unexpected keyword argument 'user_id'
Error fitting recommender: HybridRecommender.fit() got an unexpected keyword argument 'user_id'
Error fitting recommender: HybridRecommender.fit() got an unexpected keyword argument 'user_id'
Error fitting recommender: HybridRecommender.fit() got an unexpected keyword argument 'user_id'
Error fitting recommender: HybridRecommender.fit() got an unexpected keyword argument 'user_id'
Error fitting recommender: HybridRecommender.fit() got an unexpected keyword argument 'user_id'
Error fitting recommender: HybridRecommender.fit() got an unexpected keyword argument 'user_id'
Error fitting recommender: HybridRecommender.fit() got an unexpected keyword argument 'user_id'
Error fitting recommender: HybridRecommender.fit() got an unexpected keyword argument 'user_id'
Error fitting recommender: HybridRecommender.fit() got an unexpected keyword argument 'user_id'
Error fitting recommender: HybridRecommender.fit() got an unexpected keyword argument 'user_id'
Error fitting recommender: HybridRecommender.fit() got an unexpected keyword argument 'user_id'
Error fitting recommender: HybridRecommender.fit() got an unexpected keyword argument 'user_id'
Error fitting recommender: HybridRecommender.fit() got an unexpected keyword argument 'user_id'
Error fitting recommender: HybridRecommender.fit() got an unexpected keyword argument 'user_id'
Error fitting recommender: HybridRecommender.fit() got an unexpected keyword argument 'user_id'
Error fitting recommender: HybridRecommender.fit() got an unexpected keyword argument 'user_id'
Error fitting recommender: HybridRecommender.fit() got an unexpected keyword argument 'user_id'
Error fitting recommender: HybridRecommender.fit() got an unexpected keyword argument 'user_id'
Error fitting recommender: HybridRecommender.fit() got an unexpected keyword argument 'user_id'
Error fitting recommender: HybridRecommender.fit() got an unexpected keyword argument 'user_id'
Error fitting recommender: HybridRecommender.fit() got an unexpected keyword argument 'user_id'
Error fitting recommender: HybridRecommender.fit() got an unexpected keyword argument 'user_id'
Error fitting recommender: HybridRecommender.fit() got an unexpected keyword argument 'user_id'
Error fitting recommender: HybridRecommender.fit() got an unexpected keyword argument 'user_id'
Error fitting recommender: HybridRecommender.fit() got an unexpected keyword argument 'user_id'
Error fitting recommender: HybridRecommender.fit() got an unexpected keyword argument 'user_id'
Error fitting recommender: HybridRecommender.fit() got an unexpected keyword argument 'user_id'
Error fitting recommender: HybridRecommender.fit() got an unexpected keyword argument 'user_id'
Error fitting recommender: HybridRecommender.fit() got an unexpected keyword argument 'user_id'
Error fitting recommender: HybridRecommender.fit() got an unexpected keyword argument 'user_id'
Error fitting recommender: HybridRecommender.fit() got an unexpected keyword argument 'user_id'
Error fitting recommender: HybridRecommender.fit() got an unexpected keyword argument 'user_id'
Error fitting recommender: HybridRecommender.fit() got an unexpected keyword argument 'user_id'
Error fitting recommender: HybridRecommender.fit() got an unexpected keyword argument 'user_id'
Error fitting recommender: HybridRecommender.fit() got an unexpected keyword argument 'user_id'
Error fitting recommender: HybridRecommender.fit() got an unexpected keyword argument 'user_id'
Error fitting recommender: HybridRecommender.fit() got an unexpected keyword argument 'user_id'
Error fitting recommender: HybridRecommender.fit() got an unexpected keyword argument 'user_id'
Error fitting recommender: HybridRecommender.fit() got an unexpected keyword argument 'user_id'
Error fitting recommender: HybridRecommender.fit() got an unexpected keyword argument 'user_id'
Error fitting recommender: HybridRecommender.fit() got an unexpected keyword argument 'user_id'
Error fitting recommender: HybridRecommender.fit() got an unexpected keyword argument 'user_id'
Error fitting recommender: HybridRecommender.fit() got an unexpected keyword argument 'user_id'
Error fitting recommender: HybridRecommender.fit() got an unexpected keyword argument 'user_id'
Error fitting recommender: HybridRecommender.fit() got an unexpected keyword argument 'user_id'
Error fitting recommender: HybridRecommender.fit() got an unexpected keyword argument 'user_id'
Error fitting recommender: HybridRecommender.fit() got an unexpected keyword argument 'user_id'
Error fitting recommender: HybridRecommender.fit() got an unexpected keyword argument 'user_id'
Error fitting recommender: HybridRecommender.fit() got an unexpected keyword argument 'user_id'
Error fitting recommender: HybridRecommender.fit() got an unexpected keyword argument 'user_id'
Error fitting recommender: HybridRecommender.fit() got an unexpected keyword argument 'user_id'
Error fitting recommender: HybridRecommender.fit() got an unexpected keyword argument 'user_id'
Error fitting recommender: HybridRecommender.fit() got an unexpected keyword argument 'user_id'
Error fitting recommender: HybridRecommender.fit() got an unexpected keyword argument 'user_id'
Error fitting recommender: HybridRecommender.fit() got an unexpected keyword argument 'user_id'
Error fitting recommender: HybridRecommender.fit() got an unexpected keyword argument 'user_id'
Error fitting recommender: HybridRecommender.fit() got an unexpected keyword argument 'user_id'
Error fitting recommender: HybridRecommender.fit() got an unexpected keyword argument 'user_id'
Error fitting recommender: unhashable type: 'list'
Error fitting recommender: unhashable type: 'list'
Error fitting recommender: unhashable type: 'list'
Error fitting recommender: unhashable type: 'list'
Error fitting recommender: unhashable type: 'list'
Error fitting recommender: unhashable type: 'list'
Error fitting recommender: unhashable type: 'list'
Error fitting recommender: unhashable type: 'list'
Error fitting recommender: unhashable type: 'list'
Error fitting recommender: unhashable type: 'list'
Error fitting recommender: name 'df' is not defined
Error fitting recommender: name 'df' is not defined
Error fitting recommender: name 'df' is not defined
Error fitting recommender: name 'df' is not defined
Error fitting recommender: name 'df' is not defined
Error fitting recommender: name 'df' is not defined
Error fitting recommender: name 'df' is not defined
Error fitting recommender: name 'df' is not defined
Error fitting recommender: name 'df' is not defined
Error fitting recommender: name 'df' is not defined
Error fitting recommender: name 'df' is not defined
Error fitting recommender: name 'df' is not defined
Error fitting recommender: name 'merged_data' is not defined
Error fitting recommender: name 'merged_data' is not defined
Error fitting recommender: unhashable type: 'list'
Error fitting recommender: unhashable type: 'list'
Error fitting recommender: unhashable type: 'list'
Error fitting recommender: unhashable type: 'list'
Error fitting recommender: unhashable type: 'list'
Error fitting recommender: unhashable type: 'list'
Error fitting recommender: unhashable type: 'list'
Error fitting recommender: unhashable type: 'list'
Error fitting recommender: unhashable type: 'list'
Error fitting recommender: unhashable type: 'list'
Error fitting recommender: unhashable type: 'list'
Error fitting recommender: unhashable type: 'list'
Error fitting recommender: unhashable type: 'list'
Error fitting recommender: unhashable type: 'list'
Error fitting recommender: unhashable type: 'list'
Traceback (most recent call last):
  File "/app/meal_planner/tasks.py", line 60, in fit_recommender_task
    recommender.fit(merged_data)
  File "/app/meal_planner/ai_model.py", line 139, in fit
    recipes_data = merged_data[required_columns].drop_duplicates()
  File "/usr/local/lib/python3.10/site-packages/pandas/core/frame.py", line 6818, in drop_duplicates
    result = self[-self.duplicated(subset, keep=keep)]
  File "/usr/local/lib/python3.10/site-packages/pandas/core/frame.py", line 6958, in duplicated
    labels, shape = map(list, zip(*map(f, vals)))
  File "/usr/local/lib/python3.10/site-packages/pandas/core/frame.py", line 6926, in f
    labels, shape = algorithms.factorize(vals, size_hint=len(self))
  File "/usr/local/lib/python3.10/site-packages/pandas/core/algorithms.py", line 795, in factorize
    codes, uniques = factorize_array(
  File "/usr/local/lib/python3.10/site-packages/pandas/core/algorithms.py", line 595, in factorize_array
    uniques, codes = table.factorize(
  File "pandas/_libs/hashtable_class_helper.pxi", line 7281, in pandas._libs.hashtable.PyObjectHashTable.factorize
  File "pandas/_libs/hashtable_class_helper.pxi", line 7195, in pandas._libs.hashtable.PyObjectHashTable._unique
TypeError: unhashable type: 'list'
Error fitting recommender: unhashable type: 'list'
Traceback (most recent call last):
  File "/app/meal_planner/tasks.py", line 60, in fit_recommender_task
    recommender.fit(merged_data)
  File "/app/meal_planner/ai_model.py", line 139, in fit
    recipes_data = merged_data[required_columns].drop_duplicates()
  File "/usr/local/lib/python3.10/site-packages/pandas/core/frame.py", line 6818, in drop_duplicates
    result = self[-self.duplicated(subset, keep=keep)]
  File "/usr/local/lib/python3.10/site-packages/pandas/core/frame.py", line 6958, in duplicated
    labels, shape = map(list, zip(*map(f, vals)))
  File "/usr/local/lib/python3.10/site-packages/pandas/core/frame.py", line 6926, in f
    labels, shape = algorithms.factorize(vals, size_hint=len(self))
  File "/usr/local/lib/python3.10/site-packages/pandas/core/algorithms.py", line 795, in factorize
    codes, uniques = factorize_array(
  File "/usr/local/lib/python3.10/site-packages/pandas/core/algorithms.py", line 595, in factorize_array
    uniques, codes = table.factorize(
  File "pandas/_libs/hashtable_class_helper.pxi", line 7281, in pandas._libs.hashtable.PyObjectHashTable.factorize
  File "pandas/_libs/hashtable_class_helper.pxi", line 7195, in pandas._libs.hashtable.PyObjectHashTable._unique
TypeError: unhashable type: 'list'
Error fitting recommender: unhashable type: 'list'
Traceback (most recent call last):
  File "/app/meal_planner/tasks.py", line 60, in fit_recommender_task
    recommender.fit(merged_data)
  File "/app/meal_planner/ai_model.py", line 139, in fit
    recipes_data = merged_data[required_columns].drop_duplicates()
  File "/usr/local/lib/python3.10/site-packages/pandas/core/frame.py", line 6818, in drop_duplicates
    result = self[-self.duplicated(subset, keep=keep)]
  File "/usr/local/lib/python3.10/site-packages/pandas/core/frame.py", line 6958, in duplicated
    labels, shape = map(list, zip(*map(f, vals)))
  File "/usr/local/lib/python3.10/site-packages/pandas/core/frame.py", line 6926, in f
    labels, shape = algorithms.factorize(vals, size_hint=len(self))
  File "/usr/local/lib/python3.10/site-packages/pandas/core/algorithms.py", line 795, in factorize
    codes, uniques = factorize_array(
  File "/usr/local/lib/python3.10/site-packages/pandas/core/algorithms.py", line 595, in factorize_array
    uniques, codes = table.factorize(
  File "pandas/_libs/hashtable_class_helper.pxi", line 7281, in pandas._libs.hashtable.PyObjectHashTable.factorize
  File "pandas/_libs/hashtable_class_helper.pxi", line 7195, in pandas._libs.hashtable.PyObjectHashTable._unique
TypeError: unhashable type: 'list'
Error fitting recommender: unhashable type: 'list'
Traceback (most recent call last):
  File "/app/meal_planner/tasks.py", line 60, in fit_recommender_task
    recommender.fit(merged_data)
  File "/app/meal_planner/ai_model.py", line 139, in fit
    recipes_data = merged_data[required_columns].drop_duplicates()
  File "/usr/local/lib/python3.10/site-packages/pandas/core/frame.py", line 6818, in drop_duplicates
    result = self[-self.duplicated(subset, keep=keep)]
  File "/usr/local/lib/python3.10/site-packages/pandas/core/frame.py", line 6958, in duplicated
    labels, shape = map(list, zip(*map(f, vals)))
  File "/usr/local/lib/python3.10/site-packages/pandas/core/frame.py", line 6926, in f
    labels, shape = algorithms.factorize(vals, size_hint=len(self))
  File "/usr/local/lib/python3.10/site-packages/pandas/core/algorithms.py", line 795, in factorize
    codes, uniques = factorize_array(
  File "/usr/local/lib/python3.10/site-packages/pandas/core/algorithms.py", line 595, in factorize_array
    uniques, codes = table.factorize(
  File "pandas/_libs/hashtable_class_helper.pxi", line 7281, in pandas._libs.hashtable.PyObjectHashTable.factorize
  File "pandas/_libs/hashtable_class_helper.pxi", line 7195, in pandas._libs.hashtable.PyObjectHashTable._unique
TypeError: unhashable type: 'list'
Error fitting recommender: unhashable type: 'list'
Traceback (most recent call last):
  File "/app/meal_planner/tasks.py", line 60, in fit_recommender_task
    recommender.fit(merged_data)
  File "/app/meal_planner/ai_model.py", line 139, in fit
    recipes_data = merged_data[required_columns].drop_duplicates()
  File "/usr/local/lib/python3.10/site-packages/pandas/core/frame.py", line 6818, in drop_duplicates
    result = self[-self.duplicated(subset, keep=keep)]
  File "/usr/local/lib/python3.10/site-packages/pandas/core/frame.py", line 6958, in duplicated
    labels, shape = map(list, zip(*map(f, vals)))
  File "/usr/local/lib/python3.10/site-packages/pandas/core/frame.py", line 6926, in f
    labels, shape = algorithms.factorize(vals, size_hint=len(self))
  File "/usr/local/lib/python3.10/site-packages/pandas/core/algorithms.py", line 795, in factorize
    codes, uniques = factorize_array(
  File "/usr/local/lib/python3.10/site-packages/pandas/core/algorithms.py", line 595, in factorize_array
    uniques, codes = table.factorize(
  File "pandas/_libs/hashtable_class_helper.pxi", line 7281, in pandas._libs.hashtable.PyObjectHashTable.factorize
  File "pandas/_libs/hashtable_class_helper.pxi", line 7195, in pandas._libs.hashtable.PyObjectHashTable._unique
TypeError: unhashable type: 'list'
Error fitting recommender: unhashable type: 'list'
Traceback (most recent call last):
  File "/app/meal_planner/tasks.py", line 60, in fit_recommender_task
    recommender.fit(merged_data)
  File "/app/meal_planner/ai_model.py", line 139, in fit
    recipes_data = merged_data[required_columns].drop_duplicates()
  File "/usr/local/lib/python3.10/site-packages/pandas/core/frame.py", line 6818, in drop_duplicates
    result = self[-self.duplicated(subset, keep=keep)]
  File "/usr/local/lib/python3.10/site-packages/pandas/core/frame.py", line 6958, in duplicated
    labels, shape = map(list, zip(*map(f, vals)))
  File "/usr/local/lib/python3.10/site-packages/pandas/core/frame.py", line 6926, in f
    labels, shape = algorithms.factorize(vals, size_hint=len(self))
  File "/usr/local/lib/python3.10/site-packages/pandas/core/algorithms.py", line 795, in factorize
    codes, uniques = factorize_array(
  File "/usr/local/lib/python3.10/site-packages/pandas/core/algorithms.py", line 595, in factorize_array
    uniques, codes = table.factorize(
  File "pandas/_libs/hashtable_class_helper.pxi", line 7281, in pandas._libs.hashtable.PyObjectHashTable.factorize
  File "pandas/_libs/hashtable_class_helper.pxi", line 7195, in pandas._libs.hashtable.PyObjectHashTable._unique
TypeError: unhashable type: 'list'
Error fitting recommender: unhashable type: 'list'
Traceback (most recent call last):
  File "/app/meal_planner/tasks.py", line 60, in fit_recommender_task
    recommender.fit(merged_data)
  File "/app/meal_planner/ai_model.py", line 139, in fit
    recipes_data = merged_data[required_columns].drop_duplicates()
  File "/usr/local/lib/python3.10/site-packages/pandas/core/frame.py", line 6818, in drop_duplicates
    result = self[-self.duplicated(subset, keep=keep)]
  File "/usr/local/lib/python3.10/site-packages/pandas/core/frame.py", line 6958, in duplicated
    labels, shape = map(list, zip(*map(f, vals)))
  File "/usr/local/lib/python3.10/site-packages/pandas/core/frame.py", line 6926, in f
    labels, shape = algorithms.factorize(vals, size_hint=len(self))
  File "/usr/local/lib/python3.10/site-packages/pandas/core/algorithms.py", line 795, in factorize
    codes, uniques = factorize_array(
  File "/usr/local/lib/python3.10/site-packages/pandas/core/algorithms.py", line 595, in factorize_array
    uniques, codes = table.factorize(
  File "pandas/_libs/hashtable_class_helper.pxi", line 7281, in pandas._libs.hashtable.PyObjectHashTable.factorize
  File "pandas/_libs/hashtable_class_helper.pxi", line 7195, in pandas._libs.hashtable.PyObjectHashTable._unique
TypeError: unhashable type: 'list'
Error fitting recommender: unhashable type: 'list'
Traceback (most recent call last):
  File "/app/meal_planner/tasks.py", line 60, in fit_recommender_task
    recommender.fit(merged_data)
  File "/app/meal_planner/ai_model.py", line 139, in fit
    recipes_data = merged_data[required_columns].drop_duplicates()
  File "/usr/local/lib/python3.10/site-packages/pandas/core/frame.py", line 6818, in drop_duplicates
    result = self[-self.duplicated(subset, keep=keep)]
  File "/usr/local/lib/python3.10/site-packages/pandas/core/frame.py", line 6958, in duplicated
    labels, shape = map(list, zip(*map(f, vals)))
  File "/usr/local/lib/python3.10/site-packages/pandas/core/frame.py", line 6926, in f
    labels, shape = algorithms.factorize(vals, size_hint=len(self))
  File "/usr/local/lib/python3.10/site-packages/pandas/core/algorithms.py", line 795, in factorize
    codes, uniques = factorize_array(
  File "/usr/local/lib/python3.10/site-packages/pandas/core/algorithms.py", line 595, in factorize_array
    uniques, codes = table.factorize(
  File "pandas/_libs/hashtable_class_helper.pxi", line 7281, in pandas._libs.hashtable.PyObjectHashTable.factorize
  File "pandas/_libs/hashtable_class_helper.pxi", line 7195, in pandas._libs.hashtable.PyObjectHashTable._unique
TypeError: unhashable type: 'list'
Error fitting recommender: unhashable type: 'list'
Traceback (most recent call last):
  File "/app/meal_planner/tasks.py", line 60, in fit_recommender_task
    recommender.fit(merged_data)
  File "/app/meal_planner/ai_model.py", line 139, in fit
    recipes_data = merged_data[required_columns].drop_duplicates()
  File "/usr/local/lib/python3.10/site-packages/pandas/core/frame.py", line 6818, in drop_duplicates
    result = self[-self.duplicated(subset, keep=keep)]
  File "/usr/local/lib/python3.10/site-packages/pandas/core/frame.py", line 6958, in duplicated
    labels, shape = map(list, zip(*map(f, vals)))
  File "/usr/local/lib/python3.10/site-packages/pandas/core/frame.py", line 6926, in f
    labels, shape = algorithms.factorize(vals, size_hint=len(self))
  File "/usr/local/lib/python3.10/site-packages/pandas/core/algorithms.py", line 795, in factorize
    codes, uniques = factorize_array(
  File "/usr/local/lib/python3.10/site-packages/pandas/core/algorithms.py", line 595, in factorize_array
    uniques, codes = table.factorize(
  File "pandas/_libs/hashtable_class_helper.pxi", line 7281, in pandas._libs.hashtable.PyObjectHashTable.factorize
  File "pandas/_libs/hashtable_class_helper.pxi", line 7195, in pandas._libs.hashtable.PyObjectHashTable._unique
TypeError: unhashable type: 'list'
Error fitting recommender: unhashable type: 'list'
Traceback (most recent call last):
  File "/app/meal_planner/tasks.py", line 60, in fit_recommender_task
    recommender.fit(merged_data)
  File "/app/meal_planner/ai_model.py", line 139, in fit
    recipes_data = merged_data[required_columns].drop_duplicates()
  File "/usr/local/lib/python3.10/site-packages/pandas/core/frame.py", line 6818, in drop_duplicates
    result = self[-self.duplicated(subset, keep=keep)]
  File "/usr/local/lib/python3.10/site-packages/pandas/core/frame.py", line 6958, in duplicated
    labels, shape = map(list, zip(*map(f, vals)))
  File "/usr/local/lib/python3.10/site-packages/pandas/core/frame.py", line 6926, in f
    labels, shape = algorithms.factorize(vals, size_hint=len(self))
  File "/usr/local/lib/python3.10/site-packages/pandas/core/algorithms.py", line 795, in factorize
    codes, uniques = factorize_array(
  File "/usr/local/lib/python3.10/site-packages/pandas/core/algorithms.py", line 595, in factorize_array
    uniques, codes = table.factorize(
  File "pandas/_libs/hashtable_class_helper.pxi", line 7281, in pandas._libs.hashtable.PyObjectHashTable.factorize
  File "pandas/_libs/hashtable_class_helper.pxi", line 7195, in pandas._libs.hashtable.PyObjectHashTable._unique
TypeError: unhashable type: 'list'
Error fitting recommender: unhashable type: 'list'
Traceback (most recent call last):
  File "/app/meal_planner/tasks.py", line 60, in fit_recommender_task
    recommender.fit(merged_data)
  File "/app/meal_planner/ai_model.py", line 139, in fit
    self.content_recommender.fit(recipes_data)
  File "/usr/local/lib/python3.10/site-packages/pandas/core/frame.py", line 6818, in drop_duplicates
    result = self[-self.duplicated(subset, keep=keep)]
  File "/usr/local/lib/python3.10/site-packages/pandas/core/frame.py", line 6958, in duplicated
    labels, shape = map(list, zip(*map(f, vals)))
  File "/usr/local/lib/python3.10/site-packages/pandas/core/frame.py", line 6926, in f
    labels, shape = algorithms.factorize(vals, size_hint=len(self))
  File "/usr/local/lib/python3.10/site-packages/pandas/core/algorithms.py", line 795, in factorize
    codes, uniques = factorize_array(
  File "/usr/local/lib/python3.10/site-packages/pandas/core/algorithms.py", line 595, in factorize_array
    uniques, codes = table.factorize(
  File "pandas/_libs/hashtable_class_helper.pxi", line 7281, in pandas._libs.hashtable.PyObjectHashTable.factorize
  File "pandas/_libs/hashtable_class_helper.pxi", line 7195, in pandas._libs.hashtable.PyObjectHashTable._unique
TypeError: unhashable type: 'list'
Error fitting recommender: unhashable type: 'list'
Traceback (most recent call last):
  File "/app/meal_planner/tasks.py", line 60, in fit_recommender_task
    recommender.fit(merged_data)
  File "/app/meal_planner/ai_model.py", line 139, in fit
    self.content_recommender.fit(recipes_data)
  File "/usr/local/lib/python3.10/site-packages/pandas/core/frame.py", line 6818, in drop_duplicates
    result = self[-self.duplicated(subset, keep=keep)]
  File "/usr/local/lib/python3.10/site-packages/pandas/core/frame.py", line 6958, in duplicated
    labels, shape = map(list, zip(*map(f, vals)))
  File "/usr/local/lib/python3.10/site-packages/pandas/core/frame.py", line 6926, in f
    labels, shape = algorithms.factorize(vals, size_hint=len(self))
  File "/usr/local/lib/python3.10/site-packages/pandas/core/algorithms.py", line 795, in factorize
    codes, uniques = factorize_array(
  File "/usr/local/lib/python3.10/site-packages/pandas/core/algorithms.py", line 595, in factorize_array
    uniques, codes = table.factorize(
  File "pandas/_libs/hashtable_class_helper.pxi", line 7281, in pandas._libs.hashtable.PyObjectHashTable.factorize
  File "pandas/_libs/hashtable_class_helper.pxi", line 7195, in pandas._libs.hashtable.PyObjectHashTable._unique
TypeError: unhashable type: 'list'
Error fitting recommender: unhashable type: 'list'
Traceback (most recent call last):
  File "/app/meal_planner/tasks.py", line 60, in fit_recommender_task
    recommender.fit(merged_data)
  File "/app/meal_planner/ai_model.py", line 139, in fit
    self.content_recommender.fit(recipes_data)
  File "/usr/local/lib/python3.10/site-packages/pandas/core/frame.py", line 6818, in drop_duplicates
    result = self[-self.duplicated(subset, keep=keep)]
  File "/usr/local/lib/python3.10/site-packages/pandas/core/frame.py", line 6958, in duplicated
    labels, shape = map(list, zip(*map(f, vals)))
  File "/usr/local/lib/python3.10/site-packages/pandas/core/frame.py", line 6926, in f
    labels, shape = algorithms.factorize(vals, size_hint=len(self))
  File "/usr/local/lib/python3.10/site-packages/pandas/core/algorithms.py", line 795, in factorize
    codes, uniques = factorize_array(
  File "/usr/local/lib/python3.10/site-packages/pandas/core/algorithms.py", line 595, in factorize_array
    uniques, codes = table.factorize(
  File "pandas/_libs/hashtable_class_helper.pxi", line 7281, in pandas._libs.hashtable.PyObjectHashTable.factorize
  File "pandas/_libs/hashtable_class_helper.pxi", line 7195, in pandas._libs.hashtable.PyObjectHashTable._unique
TypeError: unhashable type: 'list'
Error fitting recommender: unhashable type: 'list'
Traceback (most recent call last):
  File "/app/meal_planner/tasks.py", line 60, in fit_recommender_task
    recommender.fit(merged_data)
  File "/app/meal_planner/ai_model.py", line 139, in fit
    self.content_recommender.fit(recipes_data)
  File "/usr/local/lib/python3.10/site-packages/pandas/core/frame.py", line 6818, in drop_duplicates
    result = self[-self.duplicated(subset, keep=keep)]
  File "/usr/local/lib/python3.10/site-packages/pandas/core/frame.py", line 6958, in duplicated
    labels, shape = map(list, zip(*map(f, vals)))
  File "/usr/local/lib/python3.10/site-packages/pandas/core/frame.py", line 6926, in f
    labels, shape = algorithms.factorize(vals, size_hint=len(self))
  File "/usr/local/lib/python3.10/site-packages/pandas/core/algorithms.py", line 795, in factorize
    codes, uniques = factorize_array(
  File "/usr/local/lib/python3.10/site-packages/pandas/core/algorithms.py", line 595, in factorize_array
    uniques, codes = table.factorize(
  File "pandas/_libs/hashtable_class_helper.pxi", line 7281, in pandas._libs.hashtable.PyObjectHashTable.factorize
  File "pandas/_libs/hashtable_class_helper.pxi", line 7195, in pandas._libs.hashtable.PyObjectHashTable._unique
TypeError: unhashable type: 'list'
Error fitting recommender: unhashable type: 'list'
Traceback (most recent call last):
  File "/app/meal_planner/tasks.py", line 60, in fit_recommender_task
    recommender.fit(merged_data)
  File "/app/meal_planner/ai_model.py", line 139, in fit
    self.content_recommender.fit(recipes_data)
  File "/usr/local/lib/python3.10/site-packages/pandas/core/frame.py", line 6818, in drop_duplicates
    result = self[-self.duplicated(subset, keep=keep)]
  File "/usr/local/lib/python3.10/site-packages/pandas/core/frame.py", line 6958, in duplicated
    labels, shape = map(list, zip(*map(f, vals)))
  File "/usr/local/lib/python3.10/site-packages/pandas/core/frame.py", line 6926, in f
    labels, shape = algorithms.factorize(vals, size_hint=len(self))
  File "/usr/local/lib/python3.10/site-packages/pandas/core/algorithms.py", line 795, in factorize
    codes, uniques = factorize_array(
  File "/usr/local/lib/python3.10/site-packages/pandas/core/algorithms.py", line 595, in factorize_array
    uniques, codes = table.factorize(
  File "pandas/_libs/hashtable_class_helper.pxi", line 7281, in pandas._libs.hashtable.PyObjectHashTable.factorize
  File "pandas/_libs/hashtable_class_helper.pxi", line 7195, in pandas._libs.hashtable.PyObjectHashTable._unique
TypeError: unhashable type: 'list'
Error fitting recommender: unhashable type: 'list'
Traceback (most recent call last):
  File "/app/meal_planner/tasks.py", line 60, in fit_recommender_task
    recommender.fit(merged_data)
  File "/app/meal_planner/ai_model.py", line 139, in fit
    self.content_recommender.fit(recipes_data)
  File "/usr/local/lib/python3.10/site-packages/pandas/core/frame.py", line 6818, in drop_duplicates
    result = self[-self.duplicated(subset, keep=keep)]
  File "/usr/local/lib/python3.10/site-packages/pandas/core/frame.py", line 6958, in duplicated
    labels, shape = map(list, zip(*map(f, vals)))
  File "/usr/local/lib/python3.10/site-packages/pandas/core/frame.py", line 6926, in f
    labels, shape = algorithms.factorize(vals, size_hint=len(self))
  File "/usr/local/lib/python3.10/site-packages/pandas/core/algorithms.py", line 795, in factorize
    codes, uniques = factorize_array(
  File "/usr/local/lib/python3.10/site-packages/pandas/core/algorithms.py", line 595, in factorize_array
    uniques, codes = table.factorize(
  File "pandas/_libs/hashtable_class_helper.pxi", line 7281, in pandas._libs.hashtable.PyObjectHashTable.factorize
  File "pandas/_libs/hashtable_class_helper.pxi", line 7195, in pandas._libs.hashtable.PyObjectHashTable._unique
TypeError: unhashable type: 'list'
Error fitting recommender: Can only use .str accessor with string values!
Traceback (most recent call last):
  File "/app/meal_planner/tasks.py", line 60, in fit_recommender_task
    recommender.fit(merged_data)
  File "/app/meal_planner/ai_model.py", line 139, in fit
    self.content_recommender.fit(recipes_data)
  File "/app/meal_planner/ai_model.py", line 19, in fit
    recipes_df['ingredients'] = recipes_df['ingredients'].str.strip('[]').str.split(', ')
  File "/usr/local/lib/python3.10/site-packages/pandas/core/generic.py", line 6299, in __getattr__
    return object.__getattribute__(self, name)
  File "/usr/local/lib/python3.10/site-packages/pandas/core/accessor.py", line 224, in __get__
    accessor_obj = self._accessor(obj)
  File "/usr/local/lib/python3.10/site-packages/pandas/core/strings/accessor.py", line 191, in __init__
    self._inferred_dtype = self._validate(data)
  File "/usr/local/lib/python3.10/site-packages/pandas/core/strings/accessor.py", line 245, in _validate
    raise AttributeError("Can only use .str accessor with string values!")
AttributeError: Can only use .str accessor with string values!
Error fitting recommender: Can only use .str accessor with string values!
Traceback (most recent call last):
  File "/app/meal_planner/tasks.py", line 60, in fit_recommender_task
    recommender.fit(merged_data)
  File "/app/meal_planner/ai_model.py", line 139, in fit
    self.content_recommender.fit(recipes_data)
  File "/app/meal_planner/ai_model.py", line 19, in fit
    recipes_df['ingredients'] = recipes_df['ingredients'].str.strip('[]').str.split(', ')
  File "/usr/local/lib/python3.10/site-packages/pandas/core/generic.py", line 6299, in __getattr__
    return object.__getattribute__(self, name)
  File "/usr/local/lib/python3.10/site-packages/pandas/core/accessor.py", line 224, in __get__
    accessor_obj = self._accessor(obj)
  File "/usr/local/lib/python3.10/site-packages/pandas/core/strings/accessor.py", line 191, in __init__
    self._inferred_dtype = self._validate(data)
  File "/usr/local/lib/python3.10/site-packages/pandas/core/strings/accessor.py", line 245, in _validate
    raise AttributeError("Can only use .str accessor with string values!")
AttributeError: Can only use .str accessor with string values!
Error fitting recommender: 'mae'
Traceback (most recent call last):
  File "/app/meal_planner/tasks.py", line 60, in fit_recommender_task
    recommender.fit(merged_data)
  File "/app/meal_planner/ai_model.py", line 160, in fit
    'train_mae': history['mae'],
KeyError: 'mae'
Error fitting recommender: 'mae'
Traceback (most recent call last):
  File "/app/meal_planner/tasks.py", line 60, in fit_recommender_task
    recommender.fit(merged_data)
  File "/app/meal_planner/ai_model.py", line 160, in fit
    'train_mae': history['mae'],
KeyError: 'mae'
Error fitting recommender: 'mae'
Traceback (most recent call last):
  File "/app/meal_planner/tasks.py", line 60, in fit_recommender_task
    recommender.fit(merged_data)
  File "/app/meal_planner/ai_model.py", line 160, in fit
    'train_mae': history['mae'],
KeyError: 'mae'
Error fitting recommender: 'mae'
Traceback (most recent call last):
  File "/app/meal_planner/tasks.py", line 60, in fit_recommender_task
    recommender.fit(merged_data)
  File "/app/meal_planner/ai_model.py", line 160, in fit
    'train_mae': history['mae'],
KeyError: 'mae'
Error fitting recommender: HybridRecommender.print_evaluation_summary() takes 1 positional argument but 3 were given
Traceback (most recent call last):
  File "/app/meal_planner/tasks.py", line 61, in fit_recommender_task
    recommender.print_evaluation_summary(merged_data,users_df)
TypeError: HybridRecommender.print_evaluation_summary() takes 1 positional argument but 3 were given
Error fitting recommender: name 'rrecommender' is not defined
Traceback (most recent call last):
  File "/app/meal_planner/tasks.py", line 61, in fit_recommender_task
    rrecommender.min_interactions = 5  # Set minimum interactions threshold
NameError: name 'rrecommender' is not defined
Error fitting recommender: name 'user_profiles' is not defined
Traceback (most recent call last):
  File "/app/meal_planner/tasks.py", line 62, in fit_recommender_task
    recommender.evaluate(merged_data, user_profiles)
NameError: name 'user_profiles' is not defined
Error fitting recommender: The truth value of a DataFrame is ambiguous. Use a.empty, a.bool(), a.item(), a.any() or a.all().
Traceback (most recent call last):
  File "/app/meal_planner/tasks.py", line 62, in fit_recommender_task
    recommender.evaluate(merged_data, users_df)
  File "/app/meal_planner/ai_model.py", line 346, in evaluate
    if test_data.empty or not user_profiles:
  File "/usr/local/lib/python3.10/site-packages/pandas/core/generic.py", line 1577, in __nonzero__
    raise ValueError(
ValueError: The truth value of a DataFrame is ambiguous. Use a.empty, a.bool(), a.item(), a.any() or a.all().
Error fitting recommender: The truth value of a DataFrame is ambiguous. Use a.empty, a.bool(), a.item(), a.any() or a.all().
Traceback (most recent call last):
  File "/app/meal_planner/tasks.py", line 62, in fit_recommender_task
    recommender.evaluate(merged_data)
  File "/app/meal_planner/ai_model.py", line 346, in evaluate
    if test_data.empty or not user_profiles:
  File "/usr/local/lib/python3.10/site-packages/pandas/core/generic.py", line 1577, in __nonzero__
    raise ValueError(
ValueError: The truth value of a DataFrame is ambiguous. Use a.empty, a.bool(), a.item(), a.any() or a.all().
Error fitting recommender: The truth value of a DataFrame is ambiguous. Use a.empty, a.bool(), a.item(), a.any() or a.all().
Traceback (most recent call last):
  File "/app/meal_planner/tasks.py", line 62, in fit_recommender_task
    recommender.evaluate(merged_data)
  File "/app/meal_planner/ai_model.py", line 346, in evaluate
    if test_data.empty or not user_profiles:
  File "/usr/local/lib/python3.10/site-packages/pandas/core/generic.py", line 1577, in __nonzero__
    raise ValueError(
ValueError: The truth value of a DataFrame is ambiguous. Use a.empty, a.bool(), a.item(), a.any() or a.all().
Error fitting recommender: The truth value of a DataFrame is ambiguous. Use a.empty, a.bool(), a.item(), a.any() or a.all().
Traceback (most recent call last):
  File "/app/meal_planner/tasks.py", line 62, in fit_recommender_task
    recommender.evaluate(merged_data)
  File "/app/meal_planner/ai_model.py", line 346, in evaluate
    if test_data.empty or not user_profiles:
  File "/usr/local/lib/python3.10/site-packages/pandas/core/generic.py", line 1577, in __nonzero__
    raise ValueError(
ValueError: The truth value of a DataFrame is ambiguous. Use a.empty, a.bool(), a.item(), a.any() or a.all().
Error fitting recommender: HybridRecommender.evaluate() missing 1 required positional argument: 'user_profiles'
Traceback (most recent call last):
  File "/app/meal_planner/tasks.py", line 62, in fit_recommender_task
    recommender.evaluate(merged_data)
TypeError: HybridRecommender.evaluate() missing 1 required positional argument: 'user_profiles'
Error fitting recommender: 'HybridRecommender' object has no attribute 'print_evaluation_summary'
Traceback (most recent call last):
  File "/app/meal_planner/tasks.py", line 62, in fit_recommender_task
    recommender.print_evaluation_summary()
AttributeError: 'HybridRecommender' object has no attribute 'print_evaluation_summary'
Error generating meal plan: sequence item 0: expected str instance, Ingredient found
Error generating meal plan: sequence item 0: expected str instance, Ingredient found
Recommendation generation failed: sequence item 0: expected str instance, Ingredient found
Internal Server Error: /meals/meal-plans/generate/
Recommendation generation failed: 'vegetarian'
Internal Server Error: /meals/meal-plans/generate/
Recommendation generation failed: 'vegetarian'
Internal Server Error: /meals/meal-plans/generate/
Unexpected error in meal plan generation: local variable 'dietary_codes' referenced before assignment
Traceback (most recent call last):
  File "/app/meal_planner/views.py", line 37, in post
    user_profile = self._prepare_user_profile(request)
  File "/app/meal_planner/views.py", line 142, in _prepare_user_profile
    print("Generated codes:", dietary_codes)
UnboundLocalError: local variable 'dietary_codes' referenced before assignment
Internal Server Error: /meals/meal-plans/generate/
Recommendation generation failed: 'vegetarian'
Internal Server Error: /meals/meal-plans/generate/
Unexpected error in meal plan generation: name 'json' is not defined
Traceback (most recent call last):
  File "/app/meal_planner/views.py", line 39, in post
    logger.debug(f"Generated user profile: {json.dumps(user_profile, default=str)}")
NameError: name 'json' is not defined
Internal Server Error: /meals/meal-plans/generate/
Recommendation generation failed: 'vegetarian'
Traceback (most recent call last):
  File "/usr/local/lib/python3.10/site-packages/pandas/core/indexes/base.py", line 3805, in get_loc
    return self._engine.get_loc(casted_key)
  File "index.pyx", line 167, in pandas._libs.index.IndexEngine.get_loc
  File "index.pyx", line 196, in pandas._libs.index.IndexEngine.get_loc
  File "pandas/_libs/hashtable_class_helper.pxi", line 7081, in pandas._libs.hashtable.PyObjectHashTable.get_item
  File "pandas/_libs/hashtable_class_helper.pxi", line 7089, in pandas._libs.hashtable.PyObjectHashTable.get_item
KeyError: 'vegetarian'

The above exception was the direct cause of the following exception:

Traceback (most recent call last):
  File "/app/meal_planner/views.py", line 57, in post
    meal_plans = recommender.get_recommendations(user_profile)
  File "/app/meal_planner/ai_model.py", line 252, in get_recommendations
    filtered_recs = self.rule_filter.apply_rules(user_profile, content_recs)
  File "/app/meal_planner/ai_model.py", line 51, in apply_rules
    if 'VEG' in user['dietary_preferences'] and row['vegetarian']:
  File "/usr/local/lib/python3.10/site-packages/pandas/core/series.py", line 1121, in __getitem__
    return self._get_value(key)
  File "/usr/local/lib/python3.10/site-packages/pandas/core/series.py", line 1237, in _get_value
    loc = self.index.get_loc(label)
  File "/usr/local/lib/python3.10/site-packages/pandas/core/indexes/base.py", line 3812, in get_loc
    raise KeyError(key) from err
KeyError: 'vegetarian'
Internal Server Error: /meals/meal-plans/generate/
Meal plan validation failed: ["Failed to create meal plan: name 'random' is not defined"]
Serialization failed: Cannot call `.is_valid()` as no `data=` keyword argument was passed when instantiating the serializer instance.
Internal Server Error: /meals/meal-plans/generate/
Internal Server Error: /meals/meal-plans/
Traceback (most recent call last):
  File "/usr/local/lib/python3.10/site-packages/django/db/models/fields/__init__.py", line 2123, in get_prep_value
    return int(value)
  File "/usr/local/lib/python3.10/site-packages/django/contrib/auth/models.py", line 438, in __int__
    raise TypeError(
TypeError: Cannot cast AnonymousUser to int. Are you trying to use it in place of User?

The above exception was the direct cause of the following exception:

Traceback (most recent call last):
  File "/usr/local/lib/python3.10/site-packages/django/core/handlers/exception.py", line 55, in inner
    response = get_response(request)
  File "/usr/local/lib/python3.10/site-packages/django/core/handlers/base.py", line 197, in _get_response
    response = wrapped_callback(request, *callback_args, **callback_kwargs)
  File "/usr/local/lib/python3.10/site-packages/django/views/decorators/csrf.py", line 65, in _view_wrapper
    return view_func(request, *args, **kwargs)
  File "/usr/local/lib/python3.10/site-packages/django/views/generic/base.py", line 104, in view
    return self.dispatch(request, *args, **kwargs)
  File "/usr/local/lib/python3.10/site-packages/rest_framework/views.py", line 509, in dispatch
    response = self.handle_exception(exc)
  File "/usr/local/lib/python3.10/site-packages/rest_framework/views.py", line 469, in handle_exception
    self.raise_uncaught_exception(exc)
  File "/usr/local/lib/python3.10/site-packages/rest_framework/views.py", line 480, in raise_uncaught_exception
    raise exc
  File "/usr/local/lib/python3.10/site-packages/rest_framework/views.py", line 506, in dispatch
    response = handler(request, *args, **kwargs)
  File "/app/meal_planner/views.py", line 406, in get
    meal_plans = MealPlan.objects.filter(user=request.user)
  File "/usr/local/lib/python3.10/site-packages/django/db/models/manager.py", line 87, in manager_method
    return getattr(self.get_queryset(), name)(*args, **kwargs)
  File "/usr/local/lib/python3.10/site-packages/django/db/models/query.py", line 1476, in filter
    return self._filter_or_exclude(False, args, kwargs)
  File "/usr/local/lib/python3.10/site-packages/django/db/models/query.py", line 1494, in _filter_or_exclude
    clone._filter_or_exclude_inplace(negate, args, kwargs)
  File "/usr/local/lib/python3.10/site-packages/django/db/models/query.py", line 1501, in _filter_or_exclude_inplace
    self._query.add_q(Q(*args, **kwargs))
  File "/usr/local/lib/python3.10/site-packages/django/db/models/sql/query.py", line 1609, in add_q
    clause, _ = self._add_q(q_object, self.used_aliases)
  File "/usr/local/lib/python3.10/site-packages/django/db/models/sql/query.py", line 1641, in _add_q
    child_clause, needed_inner = self.build_filter(
  File "/usr/local/lib/python3.10/site-packages/django/db/models/sql/query.py", line 1555, in build_filter
    condition = self.build_lookup(lookups, col, value)
  File "/usr/local/lib/python3.10/site-packages/django/db/models/sql/query.py", line 1385, in build_lookup
    lookup = lookup_class(lhs, rhs)
  File "/usr/local/lib/python3.10/site-packages/django/db/models/lookups.py", line 30, in __init__
    self.rhs = self.get_prep_lookup()
  File "/usr/local/lib/python3.10/site-packages/django/db/models/fields/related_lookups.py", line 156, in get_prep_lookup
    self.rhs = target_field.get_prep_value(self.rhs)
  File "/usr/local/lib/python3.10/site-packages/django/db/models/fields/__init__.py", line 2125, in get_prep_value
    raise e.__class__(
TypeError: Field 'id' expected a number but got <django.contrib.auth.models.AnonymousUser object at 0x7f7b8d99a470>.
Internal Server Error: /meals/meal-plans/
Traceback (most recent call last):
  File "/usr/local/lib/python3.10/site-packages/django/db/models/fields/__init__.py", line 2123, in get_prep_value
    return int(value)
  File "/usr/local/lib/python3.10/site-packages/django/contrib/auth/models.py", line 438, in __int__
    raise TypeError(
TypeError: Cannot cast AnonymousUser to int. Are you trying to use it in place of User?

The above exception was the direct cause of the following exception:

Traceback (most recent call last):
  File "/usr/local/lib/python3.10/site-packages/django/core/handlers/exception.py", line 55, in inner
    response = get_response(request)
  File "/usr/local/lib/python3.10/site-packages/django/core/handlers/base.py", line 197, in _get_response
    response = wrapped_callback(request, *callback_args, **callback_kwargs)
  File "/usr/local/lib/python3.10/site-packages/django/views/decorators/csrf.py", line 65, in _view_wrapper
    return view_func(request, *args, **kwargs)
  File "/usr/local/lib/python3.10/site-packages/django/views/generic/base.py", line 104, in view
    return self.dispatch(request, *args, **kwargs)
  File "/usr/local/lib/python3.10/site-packages/rest_framework/views.py", line 509, in dispatch
    response = self.handle_exception(exc)
  File "/usr/local/lib/python3.10/site-packages/rest_framework/views.py", line 469, in handle_exception
    self.raise_uncaught_exception(exc)
  File "/usr/local/lib/python3.10/site-packages/rest_framework/views.py", line 480, in raise_uncaught_exception
    raise exc
  File "/usr/local/lib/python3.10/site-packages/rest_framework/views.py", line 506, in dispatch
    response = handler(request, *args, **kwargs)
  File "/app/meal_planner/views.py", line 406, in get
    meal_plans = MealPlan.objects.filter(user=request.user)
  File "/usr/local/lib/python3.10/site-packages/django/db/models/manager.py", line 87, in manager_method
    return getattr(self.get_queryset(), name)(*args, **kwargs)
  File "/usr/local/lib/python3.10/site-packages/django/db/models/query.py", line 1476, in filter
    return self._filter_or_exclude(False, args, kwargs)
  File "/usr/local/lib/python3.10/site-packages/django/db/models/query.py", line 1494, in _filter_or_exclude
    clone._filter_or_exclude_inplace(negate, args, kwargs)
  File "/usr/local/lib/python3.10/site-packages/django/db/models/query.py", line 1501, in _filter_or_exclude_inplace
    self._query.add_q(Q(*args, **kwargs))
  File "/usr/local/lib/python3.10/site-packages/django/db/models/sql/query.py", line 1609, in add_q
    clause, _ = self._add_q(q_object, self.used_aliases)
  File "/usr/local/lib/python3.10/site-packages/django/db/models/sql/query.py", line 1641, in _add_q
    child_clause, needed_inner = self.build_filter(
  File "/usr/local/lib/python3.10/site-packages/django/db/models/sql/query.py", line 1555, in build_filter
    condition = self.build_lookup(lookups, col, value)
  File "/usr/local/lib/python3.10/site-packages/django/db/models/sql/query.py", line 1385, in build_lookup
    lookup = lookup_class(lhs, rhs)
  File "/usr/local/lib/python3.10/site-packages/django/db/models/lookups.py", line 30, in __init__
    self.rhs = self.get_prep_lookup()
  File "/usr/local/lib/python3.10/site-packages/django/db/models/fields/related_lookups.py", line 156, in get_prep_lookup
    self.rhs = target_field.get_prep_value(self.rhs)
  File "/usr/local/lib/python3.10/site-packages/django/db/models/fields/__init__.py", line 2125, in get_prep_value
    raise e.__class__(
TypeError: Field 'id' expected a number but got <django.contrib.auth.models.AnonymousUser object at 0x7f7b8d9dc0d0>.
Internal Server Error: /dietary-assessment/
Traceback (most recent call last):
  File "/usr/local/lib/python3.10/site-packages/django/db/backends/utils.py", line 105, in _execute
    return self.cursor.execute(sql, params)
psycopg2.errors.UniqueViolation: duplicate key value violates unique constraint "users_dietaryassessment_user_id_key"
DETAIL:  Key (user_id)=(8) already exists.


The above exception was the direct cause of the following exception:

Traceback (most recent call last):
  File "/usr/local/lib/python3.10/site-packages/django/core/handlers/exception.py", line 55, in inner
    response = get_response(request)
  File "/usr/local/lib/python3.10/site-packages/django/core/handlers/base.py", line 197, in _get_response
    response = wrapped_callback(request, *callback_args, **callback_kwargs)
  File "/usr/local/lib/python3.10/site-packages/django/views/decorators/csrf.py", line 65, in _view_wrapper
    return view_func(request, *args, **kwargs)
  File "/usr/local/lib/python3.10/site-packages/django/views/generic/base.py", line 104, in view
    return self.dispatch(request, *args, **kwargs)
  File "/usr/local/lib/python3.10/site-packages/rest_framework/views.py", line 509, in dispatch
    response = self.handle_exception(exc)
  File "/usr/local/lib/python3.10/site-packages/rest_framework/views.py", line 469, in handle_exception
    self.raise_uncaught_exception(exc)
  File "/usr/local/lib/python3.10/site-packages/rest_framework/views.py", line 480, in raise_uncaught_exception
    raise exc
  File "/usr/local/lib/python3.10/site-packages/rest_framework/views.py", line 506, in dispatch
    response = handler(request, *args, **kwargs)
  File "/app/users/views.py", line 816, in post
    serializer.save()
  File "/usr/local/lib/python3.10/site-packages/rest_framework/serializers.py", line 208, in save
    self.instance = self.create(validated_data)
  File "/app/users/serializers.py", line 173, in create
    return super().create(validated_data)
  File "/usr/local/lib/python3.10/site-packages/rest_framework/serializers.py", line 989, in create
    instance = ModelClass._default_manager.create(**validated_data)
  File "/usr/local/lib/python3.10/site-packages/django/db/models/manager.py", line 87, in manager_method
    return getattr(self.get_queryset(), name)(*args, **kwargs)
  File "/usr/local/lib/python3.10/site-packages/django/db/models/query.py", line 679, in create
    obj.save(force_insert=True, using=self.db)
  File "/usr/local/lib/python3.10/site-packages/django/db/models/base.py", line 891, in save
    self.save_base(
  File "/usr/local/lib/python3.10/site-packages/django/db/models/base.py", line 997, in save_base
    updated = self._save_table(
  File "/usr/local/lib/python3.10/site-packages/django/db/models/base.py", line 1160, in _save_table
    results = self._do_insert(
  File "/usr/local/lib/python3.10/site-packages/django/db/models/base.py", line 1201, in _do_insert
    return manager._insert(
  File "/usr/local/lib/python3.10/site-packages/django/db/models/manager.py", line 87, in manager_method
    return getattr(self.get_queryset(), name)(*args, **kwargs)
  File "/usr/local/lib/python3.10/site-packages/django/db/models/query.py", line 1847, in _insert
    return query.get_compiler(using=using).execute_sql(returning_fields)
  File "/usr/local/lib/python3.10/site-packages/django/db/models/sql/compiler.py", line 1836, in execute_sql
    cursor.execute(sql, params)
  File "/usr/local/lib/python3.10/site-packages/django/db/backends/utils.py", line 122, in execute
    return super().execute(sql, params)
  File "/usr/local/lib/python3.10/site-packages/django/db/backends/utils.py", line 79, in execute
    return self._execute_with_wrappers(
  File "/usr/local/lib/python3.10/site-packages/django/db/backends/utils.py", line 92, in _execute_with_wrappers
    return executor(sql, params, many, context)
  File "/usr/local/lib/python3.10/site-packages/django/db/backends/utils.py", line 100, in _execute
    with self.db.wrap_database_errors:
  File "/usr/local/lib/python3.10/site-packages/django/db/utils.py", line 91, in __exit__
    raise dj_exc_value.with_traceback(traceback) from exc_value
  File "/usr/local/lib/python3.10/site-packages/django/db/backends/utils.py", line 105, in _execute
    return self.cursor.execute(sql, params)
django.db.utils.IntegrityError: duplicate key value violates unique constraint "users_dietaryassessment_user_id_key"
DETAIL:  Key (user_id)=(8) already exists.

Internal Server Error: /meals/meal-plans/brNshaVr/customize/
Traceback (most recent call last):
  File "/usr/local/lib/python3.10/site-packages/django/core/handlers/exception.py", line 55, in inner
    response = get_response(request)
  File "/usr/local/lib/python3.10/site-packages/django/core/handlers/base.py", line 197, in _get_response
    response = wrapped_callback(request, *callback_args, **callback_kwargs)
  File "/usr/local/lib/python3.10/site-packages/django/views/decorators/csrf.py", line 65, in _view_wrapper
    return view_func(request, *args, **kwargs)
  File "/usr/local/lib/python3.10/site-packages/django/views/generic/base.py", line 104, in view
    return self.dispatch(request, *args, **kwargs)
  File "/usr/local/lib/python3.10/site-packages/rest_framework/views.py", line 509, in dispatch
    response = self.handle_exception(exc)
  File "/usr/local/lib/python3.10/site-packages/rest_framework/views.py", line 469, in handle_exception
    self.raise_uncaught_exception(exc)
  File "/usr/local/lib/python3.10/site-packages/rest_framework/views.py", line 480, in raise_uncaught_exception
    raise exc
  File "/usr/local/lib/python3.10/site-packages/rest_framework/views.py", line 506, in dispatch
    response = handler(request, *args, **kwargs)
  File "/app/meal_planner/views.py", line 524, in put
    return Response(serializer.data)
  File "/usr/local/lib/python3.10/site-packages/rest_framework/serializers.py", line 571, in data
    ret = super().data
  File "/usr/local/lib/python3.10/site-packages/rest_framework/serializers.py", line 249, in data
    self._data = self.to_representation(self.instance)
  File "/app/meal_planner/serializers.py", line 18, in to_representation
    data = super().to_representation(instance)
  File "/usr/local/lib/python3.10/site-packages/rest_framework/serializers.py", line 538, in to_representation
    ret[field.field_name] = field.to_representation(attribute)
  File "/usr/local/lib/python3.10/site-packages/rest_framework/fields.py", line 1870, in to_representation
    return method(value)
  File "/app/meal_planner/serializers.py", line 15, in get_nutritional_composition
    return obj.calculate_nutritional_composition()
  File "/app/meal_planner/models.py", line 80, in calculate_nutritional_composition
    recipe = Recipe.objects.get(name=meal)  # Fetch the actual recipe object by name
  File "/usr/local/lib/python3.10/site-packages/django/db/models/manager.py", line 87, in manager_method
    return getattr(self.get_queryset(), name)(*args, **kwargs)
  File "/usr/local/lib/python3.10/site-packages/django/db/models/query.py", line 649, in get
    raise self.model.DoesNotExist(
users.models.Recipe.DoesNotExist: Recipe matching query does not exist.
Internal Server Error: /meals/meal-plans/brNshaVr/
Traceback (most recent call last):
  File "/usr/local/lib/python3.10/site-packages/django/core/handlers/exception.py", line 55, in inner
    response = get_response(request)
  File "/usr/local/lib/python3.10/site-packages/django/core/handlers/base.py", line 197, in _get_response
    response = wrapped_callback(request, *callback_args, **callback_kwargs)
  File "/usr/local/lib/python3.10/site-packages/django/views/decorators/csrf.py", line 65, in _view_wrapper
    return view_func(request, *args, **kwargs)
  File "/usr/local/lib/python3.10/site-packages/django/views/generic/base.py", line 104, in view
    return self.dispatch(request, *args, **kwargs)
  File "/usr/local/lib/python3.10/site-packages/rest_framework/views.py", line 509, in dispatch
    response = self.handle_exception(exc)
  File "/usr/local/lib/python3.10/site-packages/rest_framework/views.py", line 469, in handle_exception
    self.raise_uncaught_exception(exc)
  File "/usr/local/lib/python3.10/site-packages/rest_framework/views.py", line 480, in raise_uncaught_exception
    raise exc
  File "/usr/local/lib/python3.10/site-packages/rest_framework/views.py", line 506, in dispatch
    response = handler(request, *args, **kwargs)
  File "/app/meal_planner/views.py", line 407, in get
    return Response(serializer.data, status=status.HTTP_200_OK)
  File "/usr/local/lib/python3.10/site-packages/rest_framework/serializers.py", line 571, in data
    ret = super().data
  File "/usr/local/lib/python3.10/site-packages/rest_framework/serializers.py", line 249, in data
    self._data = self.to_representation(self.instance)
  File "/app/meal_planner/serializers.py", line 18, in to_representation
    data = super().to_representation(instance)
  File "/usr/local/lib/python3.10/site-packages/rest_framework/serializers.py", line 538, in to_representation
    ret[field.field_name] = field.to_representation(attribute)
  File "/usr/local/lib/python3.10/site-packages/rest_framework/fields.py", line 1870, in to_representation
    return method(value)
  File "/app/meal_planner/serializers.py", line 15, in get_nutritional_composition
    return obj.calculate_nutritional_composition()
  File "/app/meal_planner/models.py", line 80, in calculate_nutritional_composition
    recipe = Recipe.objects.get(name=meal)  # Fetch the actual recipe object by name
  File "/usr/local/lib/python3.10/site-packages/django/db/models/manager.py", line 87, in manager_method
    return getattr(self.get_queryset(), name)(*args, **kwargs)
  File "/usr/local/lib/python3.10/site-packages/django/db/models/query.py", line 649, in get
    raise self.model.DoesNotExist(
users.models.Recipe.DoesNotExist: Recipe matching query does not exist.
Internal Server Error: /meals/meal-plans/brNshaVr/
Traceback (most recent call last):
  File "/usr/local/lib/python3.10/site-packages/django/core/handlers/exception.py", line 55, in inner
    response = get_response(request)
  File "/usr/local/lib/python3.10/site-packages/django/core/handlers/base.py", line 197, in _get_response
    response = wrapped_callback(request, *callback_args, **callback_kwargs)
  File "/usr/local/lib/python3.10/site-packages/django/views/decorators/csrf.py", line 65, in _view_wrapper
    return view_func(request, *args, **kwargs)
  File "/usr/local/lib/python3.10/site-packages/django/views/generic/base.py", line 104, in view
    return self.dispatch(request, *args, **kwargs)
  File "/usr/local/lib/python3.10/site-packages/rest_framework/views.py", line 509, in dispatch
    response = self.handle_exception(exc)
  File "/usr/local/lib/python3.10/site-packages/rest_framework/views.py", line 469, in handle_exception
    self.raise_uncaught_exception(exc)
  File "/usr/local/lib/python3.10/site-packages/rest_framework/views.py", line 480, in raise_uncaught_exception
    raise exc
  File "/usr/local/lib/python3.10/site-packages/rest_framework/views.py", line 506, in dispatch
    response = handler(request, *args, **kwargs)
  File "/app/meal_planner/views.py", line 407, in get
    return Response(serializer.data, status=status.HTTP_200_OK)
  File "/usr/local/lib/python3.10/site-packages/rest_framework/serializers.py", line 571, in data
    ret = super().data
  File "/usr/local/lib/python3.10/site-packages/rest_framework/serializers.py", line 249, in data
    self._data = self.to_representation(self.instance)
  File "/app/meal_planner/serializers.py", line 18, in to_representation
    data = super().to_representation(instance)
  File "/usr/local/lib/python3.10/site-packages/rest_framework/serializers.py", line 538, in to_representation
    ret[field.field_name] = field.to_representation(attribute)
  File "/usr/local/lib/python3.10/site-packages/rest_framework/fields.py", line 1870, in to_representation
    return method(value)
  File "/app/meal_planner/serializers.py", line 15, in get_nutritional_composition
    return obj.calculate_nutritional_composition()
  File "/app/meal_planner/models.py", line 80, in calculate_nutritional_composition
    recipe = Recipe.objects.get(name=meal)  # Fetch the actual recipe object by name
  File "/usr/local/lib/python3.10/site-packages/django/db/models/manager.py", line 87, in manager_method
    return getattr(self.get_queryset(), name)(*args, **kwargs)
  File "/usr/local/lib/python3.10/site-packages/django/db/models/query.py", line 649, in get
    raise self.model.DoesNotExist(
users.models.Recipe.DoesNotExist: Recipe matching query does not exist.
Internal Server Error: /meals/meal-plans/brNshaVr/
Traceback (most recent call last):
  File "/usr/local/lib/python3.10/site-packages/django/core/handlers/exception.py", line 55, in inner
    response = get_response(request)
  File "/usr/local/lib/python3.10/site-packages/django/core/handlers/base.py", line 197, in _get_response
    response = wrapped_callback(request, *callback_args, **callback_kwargs)
  File "/usr/local/lib/python3.10/site-packages/django/views/decorators/csrf.py", line 65, in _view_wrapper
    return view_func(request, *args, **kwargs)
  File "/usr/local/lib/python3.10/site-packages/django/views/generic/base.py", line 104, in view
    return self.dispatch(request, *args, **kwargs)
  File "/usr/local/lib/python3.10/site-packages/rest_framework/views.py", line 509, in dispatch
    response = self.handle_exception(exc)
  File "/usr/local/lib/python3.10/site-packages/rest_framework/views.py", line 469, in handle_exception
    self.raise_uncaught_exception(exc)
  File "/usr/local/lib/python3.10/site-packages/rest_framework/views.py", line 480, in raise_uncaught_exception
    raise exc
  File "/usr/local/lib/python3.10/site-packages/rest_framework/views.py", line 506, in dispatch
    response = handler(request, *args, **kwargs)
  File "/app/meal_planner/views.py", line 407, in get
    return Response(serializer.data, status=status.HTTP_200_OK)
  File "/usr/local/lib/python3.10/site-packages/rest_framework/serializers.py", line 571, in data
    ret = super().data
  File "/usr/local/lib/python3.10/site-packages/rest_framework/serializers.py", line 249, in data
    self._data = self.to_representation(self.instance)
  File "/app/meal_planner/serializers.py", line 18, in to_representation
    data = super().to_representation(instance)
  File "/usr/local/lib/python3.10/site-packages/rest_framework/serializers.py", line 538, in to_representation
    ret[field.field_name] = field.to_representation(attribute)
  File "/usr/local/lib/python3.10/site-packages/rest_framework/fields.py", line 1870, in to_representation
    return method(value)
  File "/app/meal_planner/serializers.py", line 15, in get_nutritional_composition
    return obj.calculate_nutritional_composition()
  File "/app/meal_planner/models.py", line 80, in calculate_nutritional_composition
    recipe = Recipe.objects.get(name=meal)  # Fetch the actual recipe object by name
  File "/usr/local/lib/python3.10/site-packages/django/db/models/manager.py", line 87, in manager_method
    return getattr(self.get_queryset(), name)(*args, **kwargs)
  File "/usr/local/lib/python3.10/site-packages/django/db/models/query.py", line 649, in get
    raise self.model.DoesNotExist(
users.models.Recipe.DoesNotExist: Recipe matching query does not exist.
Internal Server Error: /meals/meal-plans/brNshaVr/
Traceback (most recent call last):
  File "/usr/local/lib/python3.10/site-packages/django/core/handlers/exception.py", line 55, in inner
    response = get_response(request)
  File "/usr/local/lib/python3.10/site-packages/django/core/handlers/base.py", line 197, in _get_response
    response = wrapped_callback(request, *callback_args, **callback_kwargs)
  File "/usr/local/lib/python3.10/site-packages/django/views/decorators/csrf.py", line 65, in _view_wrapper
    return view_func(request, *args, **kwargs)
  File "/usr/local/lib/python3.10/site-packages/django/views/generic/base.py", line 104, in view
    return self.dispatch(request, *args, **kwargs)
  File "/usr/local/lib/python3.10/site-packages/rest_framework/views.py", line 509, in dispatch
    response = self.handle_exception(exc)
  File "/usr/local/lib/python3.10/site-packages/rest_framework/views.py", line 469, in handle_exception
    self.raise_uncaught_exception(exc)
  File "/usr/local/lib/python3.10/site-packages/rest_framework/views.py", line 480, in raise_uncaught_exception
    raise exc
  File "/usr/local/lib/python3.10/site-packages/rest_framework/views.py", line 506, in dispatch
    response = handler(request, *args, **kwargs)
  File "/app/meal_planner/views.py", line 407, in get
    return Response(serializer.data, status=status.HTTP_200_OK)
  File "/usr/local/lib/python3.10/site-packages/rest_framework/serializers.py", line 571, in data
    ret = super().data
  File "/usr/local/lib/python3.10/site-packages/rest_framework/serializers.py", line 249, in data
    self._data = self.to_representation(self.instance)
  File "/app/meal_planner/serializers.py", line 18, in to_representation
    data = super().to_representation(instance)
  File "/usr/local/lib/python3.10/site-packages/rest_framework/serializers.py", line 538, in to_representation
    ret[field.field_name] = field.to_representation(attribute)
  File "/usr/local/lib/python3.10/site-packages/rest_framework/fields.py", line 1870, in to_representation
    return method(value)
  File "/app/meal_planner/serializers.py", line 15, in get_nutritional_composition
    return obj.calculate_nutritional_composition()
  File "/app/meal_planner/models.py", line 80, in calculate_nutritional_composition
    recipe = Recipe.objects.get(name=meal)  # Fetch the actual recipe object by name
  File "/usr/local/lib/python3.10/site-packages/django/db/models/manager.py", line 87, in manager_method
    return getattr(self.get_queryset(), name)(*args, **kwargs)
  File "/usr/local/lib/python3.10/site-packages/django/db/models/query.py", line 649, in get
    raise self.model.DoesNotExist(
users.models.Recipe.DoesNotExist: Recipe matching query does not exist.
Internal Server Error: /meals/meal-plans/brNshaVr/
Traceback (most recent call last):
  File "/usr/local/lib/python3.10/site-packages/django/core/handlers/exception.py", line 55, in inner
    response = get_response(request)
  File "/usr/local/lib/python3.10/site-packages/django/core/handlers/base.py", line 197, in _get_response
    response = wrapped_callback(request, *callback_args, **callback_kwargs)
  File "/usr/local/lib/python3.10/site-packages/django/views/decorators/csrf.py", line 65, in _view_wrapper
    return view_func(request, *args, **kwargs)
  File "/usr/local/lib/python3.10/site-packages/django/views/generic/base.py", line 104, in view
    return self.dispatch(request, *args, **kwargs)
  File "/usr/local/lib/python3.10/site-packages/rest_framework/views.py", line 509, in dispatch
    response = self.handle_exception(exc)
  File "/usr/local/lib/python3.10/site-packages/rest_framework/views.py", line 469, in handle_exception
    self.raise_uncaught_exception(exc)
  File "/usr/local/lib/python3.10/site-packages/rest_framework/views.py", line 480, in raise_uncaught_exception
    raise exc
  File "/usr/local/lib/python3.10/site-packages/rest_framework/views.py", line 506, in dispatch
    response = handler(request, *args, **kwargs)
  File "/app/meal_planner/views.py", line 407, in get
    return Response(serializer.data, status=status.HTTP_200_OK)
  File "/usr/local/lib/python3.10/site-packages/rest_framework/serializers.py", line 571, in data
    ret = super().data
  File "/usr/local/lib/python3.10/site-packages/rest_framework/serializers.py", line 249, in data
    self._data = self.to_representation(self.instance)
  File "/app/meal_planner/serializers.py", line 18, in to_representation
    data = super().to_representation(instance)
  File "/usr/local/lib/python3.10/site-packages/rest_framework/serializers.py", line 538, in to_representation
    ret[field.field_name] = field.to_representation(attribute)
  File "/usr/local/lib/python3.10/site-packages/rest_framework/fields.py", line 1870, in to_representation
    return method(value)
  File "/app/meal_planner/serializers.py", line 15, in get_nutritional_composition
    return obj.calculate_nutritional_composition()
  File "/app/meal_planner/models.py", line 80, in calculate_nutritional_composition
    recipe = Recipe.objects.get(name=meal)  # Fetch the actual recipe object by name
  File "/usr/local/lib/python3.10/site-packages/django/db/models/manager.py", line 87, in manager_method
    return getattr(self.get_queryset(), name)(*args, **kwargs)
  File "/usr/local/lib/python3.10/site-packages/django/db/models/query.py", line 649, in get
    raise self.model.DoesNotExist(
users.models.Recipe.DoesNotExist: Recipe matching query does not exist.
Internal Server Error: /meals/meal-plans/brNshaVr/
Traceback (most recent call last):
  File "/usr/local/lib/python3.10/site-packages/django/core/handlers/exception.py", line 55, in inner
    response = get_response(request)
  File "/usr/local/lib/python3.10/site-packages/django/core/handlers/base.py", line 197, in _get_response
    response = wrapped_callback(request, *callback_args, **callback_kwargs)
  File "/usr/local/lib/python3.10/site-packages/django/views/decorators/csrf.py", line 65, in _view_wrapper
    return view_func(request, *args, **kwargs)
  File "/usr/local/lib/python3.10/site-packages/django/views/generic/base.py", line 104, in view
    return self.dispatch(request, *args, **kwargs)
  File "/usr/local/lib/python3.10/site-packages/rest_framework/views.py", line 509, in dispatch
    response = self.handle_exception(exc)
  File "/usr/local/lib/python3.10/site-packages/rest_framework/views.py", line 469, in handle_exception
    self.raise_uncaught_exception(exc)
  File "/usr/local/lib/python3.10/site-packages/rest_framework/views.py", line 480, in raise_uncaught_exception
    raise exc
  File "/usr/local/lib/python3.10/site-packages/rest_framework/views.py", line 506, in dispatch
    response = handler(request, *args, **kwargs)
  File "/app/meal_planner/views.py", line 407, in get
    return Response(serializer.data, status=status.HTTP_200_OK)
  File "/usr/local/lib/python3.10/site-packages/rest_framework/serializers.py", line 571, in data
    ret = super().data
  File "/usr/local/lib/python3.10/site-packages/rest_framework/serializers.py", line 249, in data
    self._data = self.to_representation(self.instance)
  File "/app/meal_planner/serializers.py", line 18, in to_representation
    data = super().to_representation(instance)
  File "/usr/local/lib/python3.10/site-packages/rest_framework/serializers.py", line 538, in to_representation
    ret[field.field_name] = field.to_representation(attribute)
  File "/usr/local/lib/python3.10/site-packages/rest_framework/fields.py", line 1870, in to_representation
    return method(value)
  File "/app/meal_planner/serializers.py", line 15, in get_nutritional_composition
    return obj.calculate_nutritional_composition()
  File "/app/meal_planner/models.py", line 80, in calculate_nutritional_composition
    recipe = Recipe.objects.get(name=meal)  # Fetch the actual recipe object by name
  File "/usr/local/lib/python3.10/site-packages/django/db/models/manager.py", line 87, in manager_method
    return getattr(self.get_queryset(), name)(*args, **kwargs)
  File "/usr/local/lib/python3.10/site-packages/django/db/models/query.py", line 649, in get
    raise self.model.DoesNotExist(
users.models.Recipe.DoesNotExist: Recipe matching query does not exist.
Internal Server Error: /meals/meal-plans/
Traceback (most recent call last):
  File "/usr/local/lib/python3.10/site-packages/django/core/handlers/exception.py", line 55, in inner
    response = get_response(request)
  File "/usr/local/lib/python3.10/site-packages/django/core/handlers/base.py", line 197, in _get_response
    response = wrapped_callback(request, *callback_args, **callback_kwargs)
  File "/usr/local/lib/python3.10/site-packages/django/views/decorators/csrf.py", line 65, in _view_wrapper
    return view_func(request, *args, **kwargs)
  File "/usr/local/lib/python3.10/site-packages/django/views/generic/base.py", line 104, in view
    return self.dispatch(request, *args, **kwargs)
  File "/usr/local/lib/python3.10/site-packages/rest_framework/views.py", line 509, in dispatch
    response = self.handle_exception(exc)
  File "/usr/local/lib/python3.10/site-packages/rest_framework/views.py", line 469, in handle_exception
    self.raise_uncaught_exception(exc)
  File "/usr/local/lib/python3.10/site-packages/rest_framework/views.py", line 480, in raise_uncaught_exception
    raise exc
  File "/usr/local/lib/python3.10/site-packages/rest_framework/views.py", line 506, in dispatch
    response = handler(request, *args, **kwargs)
  File "/app/meal_planner/views.py", line 439, in get
    return Response(serializer.data, status=status.HTTP_200_OK)
  File "/usr/local/lib/python3.10/site-packages/rest_framework/serializers.py", line 795, in data
    ret = super().data
  File "/usr/local/lib/python3.10/site-packages/rest_framework/serializers.py", line 249, in data
    self._data = self.to_representation(self.instance)
  File "/usr/local/lib/python3.10/site-packages/rest_framework/serializers.py", line 713, in to_representation
    return [
  File "/usr/local/lib/python3.10/site-packages/rest_framework/serializers.py", line 714, in <listcomp>
    self.child.to_representation(item) for item in iterable
  File "/app/meal_planner/serializers.py", line 18, in to_representation
    data = super().to_representation(instance)
  File "/usr/local/lib/python3.10/site-packages/rest_framework/serializers.py", line 538, in to_representation
    ret[field.field_name] = field.to_representation(attribute)
  File "/usr/local/lib/python3.10/site-packages/rest_framework/fields.py", line 1870, in to_representation
    return method(value)
  File "/app/meal_planner/serializers.py", line 15, in get_nutritional_composition
    return obj.calculate_nutritional_composition()
  File "/app/meal_planner/models.py", line 80, in calculate_nutritional_composition
    recipe = Recipe.objects.get(name=meal)  # Fetch the actual recipe object by name
  File "/usr/local/lib/python3.10/site-packages/django/db/models/manager.py", line 87, in manager_method
    return getattr(self.get_queryset(), name)(*args, **kwargs)
  File "/usr/local/lib/python3.10/site-packages/django/db/models/query.py", line 649, in get
    raise self.model.DoesNotExist(
users.models.Recipe.DoesNotExist: Recipe matching query does not exist.
Internal Server Error: /meals/meal-plans/
Traceback (most recent call last):
  File "/usr/local/lib/python3.10/site-packages/django/core/handlers/exception.py", line 55, in inner
    response = get_response(request)
  File "/usr/local/lib/python3.10/site-packages/django/core/handlers/base.py", line 197, in _get_response
    response = wrapped_callback(request, *callback_args, **callback_kwargs)
  File "/usr/local/lib/python3.10/site-packages/django/views/decorators/csrf.py", line 65, in _view_wrapper
    return view_func(request, *args, **kwargs)
  File "/usr/local/lib/python3.10/site-packages/django/views/generic/base.py", line 104, in view
    return self.dispatch(request, *args, **kwargs)
  File "/usr/local/lib/python3.10/site-packages/rest_framework/views.py", line 509, in dispatch
    response = self.handle_exception(exc)
  File "/usr/local/lib/python3.10/site-packages/rest_framework/views.py", line 469, in handle_exception
    self.raise_uncaught_exception(exc)
  File "/usr/local/lib/python3.10/site-packages/rest_framework/views.py", line 480, in raise_uncaught_exception
    raise exc
  File "/usr/local/lib/python3.10/site-packages/rest_framework/views.py", line 506, in dispatch
    response = handler(request, *args, **kwargs)
  File "/app/meal_planner/views.py", line 439, in get
    return Response(serializer.data, status=status.HTTP_200_OK)
  File "/usr/local/lib/python3.10/site-packages/rest_framework/serializers.py", line 795, in data
    ret = super().data
  File "/usr/local/lib/python3.10/site-packages/rest_framework/serializers.py", line 249, in data
    self._data = self.to_representation(self.instance)
  File "/usr/local/lib/python3.10/site-packages/rest_framework/serializers.py", line 713, in to_representation
    return [
  File "/usr/local/lib/python3.10/site-packages/rest_framework/serializers.py", line 714, in <listcomp>
    self.child.to_representation(item) for item in iterable
  File "/app/meal_planner/serializers.py", line 18, in to_representation
    data = super().to_representation(instance)
  File "/usr/local/lib/python3.10/site-packages/rest_framework/serializers.py", line 538, in to_representation
    ret[field.field_name] = field.to_representation(attribute)
  File "/usr/local/lib/python3.10/site-packages/rest_framework/fields.py", line 1870, in to_representation
    return method(value)
  File "/app/meal_planner/serializers.py", line 15, in get_nutritional_composition
    return obj.calculate_nutritional_composition()
  File "/app/meal_planner/models.py", line 80, in calculate_nutritional_composition
    recipe = Recipe.objects.get(name=meal)  # Fetch the actual recipe object by name
  File "/usr/local/lib/python3.10/site-packages/django/db/models/manager.py", line 87, in manager_method
    return getattr(self.get_queryset(), name)(*args, **kwargs)
  File "/usr/local/lib/python3.10/site-packages/django/db/models/query.py", line 649, in get
    raise self.model.DoesNotExist(
users.models.Recipe.DoesNotExist: Recipe matching query does not exist.
Internal Server Error: /meals/meal-plans/
Traceback (most recent call last):
  File "/usr/local/lib/python3.10/site-packages/django/core/handlers/exception.py", line 55, in inner
    response = get_response(request)
  File "/usr/local/lib/python3.10/site-packages/django/core/handlers/base.py", line 197, in _get_response
    response = wrapped_callback(request, *callback_args, **callback_kwargs)
  File "/usr/local/lib/python3.10/site-packages/django/views/decorators/csrf.py", line 65, in _view_wrapper
    return view_func(request, *args, **kwargs)
  File "/usr/local/lib/python3.10/site-packages/django/views/generic/base.py", line 104, in view
    return self.dispatch(request, *args, **kwargs)
  File "/usr/local/lib/python3.10/site-packages/rest_framework/views.py", line 509, in dispatch
    response = self.handle_exception(exc)
  File "/usr/local/lib/python3.10/site-packages/rest_framework/views.py", line 469, in handle_exception
    self.raise_uncaught_exception(exc)
  File "/usr/local/lib/python3.10/site-packages/rest_framework/views.py", line 480, in raise_uncaught_exception
    raise exc
  File "/usr/local/lib/python3.10/site-packages/rest_framework/views.py", line 506, in dispatch
    response = handler(request, *args, **kwargs)
  File "/app/meal_planner/views.py", line 439, in get
    return Response(serializer.data, status=status.HTTP_200_OK)
  File "/usr/local/lib/python3.10/site-packages/rest_framework/serializers.py", line 795, in data
    ret = super().data
  File "/usr/local/lib/python3.10/site-packages/rest_framework/serializers.py", line 249, in data
    self._data = self.to_representation(self.instance)
  File "/usr/local/lib/python3.10/site-packages/rest_framework/serializers.py", line 713, in to_representation
    return [
  File "/usr/local/lib/python3.10/site-packages/rest_framework/serializers.py", line 714, in <listcomp>
    self.child.to_representation(item) for item in iterable
  File "/app/meal_planner/serializers.py", line 18, in to_representation
    data = super().to_representation(instance)
  File "/usr/local/lib/python3.10/site-packages/rest_framework/serializers.py", line 538, in to_representation
    ret[field.field_name] = field.to_representation(attribute)
  File "/usr/local/lib/python3.10/site-packages/rest_framework/fields.py", line 1870, in to_representation
    return method(value)
  File "/app/meal_planner/serializers.py", line 15, in get_nutritional_composition
    return obj.calculate_nutritional_composition()
  File "/app/meal_planner/models.py", line 80, in calculate_nutritional_composition
    recipe = Recipe.objects.get(name=meal)  # Fetch the actual recipe object by name
  File "/usr/local/lib/python3.10/site-packages/django/db/models/manager.py", line 87, in manager_method
    return getattr(self.get_queryset(), name)(*args, **kwargs)
  File "/usr/local/lib/python3.10/site-packages/django/db/models/query.py", line 649, in get
    raise self.model.DoesNotExist(
users.models.Recipe.DoesNotExist: Recipe matching query does not exist.
Internal Server Error: /meals/meal-plans/
Traceback (most recent call last):
  File "/usr/local/lib/python3.10/site-packages/django/core/handlers/exception.py", line 55, in inner
    response = get_response(request)
  File "/usr/local/lib/python3.10/site-packages/django/core/handlers/base.py", line 197, in _get_response
    response = wrapped_callback(request, *callback_args, **callback_kwargs)
  File "/usr/local/lib/python3.10/site-packages/django/views/decorators/csrf.py", line 65, in _view_wrapper
    return view_func(request, *args, **kwargs)
  File "/usr/local/lib/python3.10/site-packages/django/views/generic/base.py", line 104, in view
    return self.dispatch(request, *args, **kwargs)
  File "/usr/local/lib/python3.10/site-packages/rest_framework/views.py", line 509, in dispatch
    response = self.handle_exception(exc)
  File "/usr/local/lib/python3.10/site-packages/rest_framework/views.py", line 469, in handle_exception
    self.raise_uncaught_exception(exc)
  File "/usr/local/lib/python3.10/site-packages/rest_framework/views.py", line 480, in raise_uncaught_exception
    raise exc
  File "/usr/local/lib/python3.10/site-packages/rest_framework/views.py", line 506, in dispatch
    response = handler(request, *args, **kwargs)
  File "/app/meal_planner/views.py", line 439, in get
    return Response(serializer.data, status=status.HTTP_200_OK)
  File "/usr/local/lib/python3.10/site-packages/rest_framework/serializers.py", line 795, in data
    ret = super().data
  File "/usr/local/lib/python3.10/site-packages/rest_framework/serializers.py", line 249, in data
    self._data = self.to_representation(self.instance)
  File "/usr/local/lib/python3.10/site-packages/rest_framework/serializers.py", line 713, in to_representation
    return [
  File "/usr/local/lib/python3.10/site-packages/rest_framework/serializers.py", line 714, in <listcomp>
    self.child.to_representation(item) for item in iterable
  File "/app/meal_planner/serializers.py", line 18, in to_representation
    data = super().to_representation(instance)
  File "/usr/local/lib/python3.10/site-packages/rest_framework/serializers.py", line 538, in to_representation
    ret[field.field_name] = field.to_representation(attribute)
  File "/usr/local/lib/python3.10/site-packages/rest_framework/fields.py", line 1870, in to_representation
    return method(value)
  File "/app/meal_planner/serializers.py", line 15, in get_nutritional_composition
    return obj.calculate_nutritional_composition()
  File "/app/meal_planner/models.py", line 80, in calculate_nutritional_composition
    recipe = Recipe.objects.get(name=meal)  # Fetch the actual recipe object by name
  File "/usr/local/lib/python3.10/site-packages/django/db/models/manager.py", line 87, in manager_method
    return getattr(self.get_queryset(), name)(*args, **kwargs)
  File "/usr/local/lib/python3.10/site-packages/django/db/models/query.py", line 649, in get
    raise self.model.DoesNotExist(
users.models.Recipe.DoesNotExist: Recipe matching query does not exist.
Internal Server Error: /meals/meal-plans/
Traceback (most recent call last):
  File "/usr/local/lib/python3.10/site-packages/django/core/handlers/exception.py", line 55, in inner
    response = get_response(request)
  File "/usr/local/lib/python3.10/site-packages/django/core/handlers/base.py", line 197, in _get_response
    response = wrapped_callback(request, *callback_args, **callback_kwargs)
  File "/usr/local/lib/python3.10/site-packages/django/views/decorators/csrf.py", line 65, in _view_wrapper
    return view_func(request, *args, **kwargs)
  File "/usr/local/lib/python3.10/site-packages/django/views/generic/base.py", line 104, in view
    return self.dispatch(request, *args, **kwargs)
  File "/usr/local/lib/python3.10/site-packages/rest_framework/views.py", line 509, in dispatch
    response = self.handle_exception(exc)
  File "/usr/local/lib/python3.10/site-packages/rest_framework/views.py", line 469, in handle_exception
    self.raise_uncaught_exception(exc)
  File "/usr/local/lib/python3.10/site-packages/rest_framework/views.py", line 480, in raise_uncaught_exception
    raise exc
  File "/usr/local/lib/python3.10/site-packages/rest_framework/views.py", line 506, in dispatch
    response = handler(request, *args, **kwargs)
  File "/app/meal_planner/views.py", line 439, in get
    return Response(serializer.data, status=status.HTTP_200_OK)
  File "/usr/local/lib/python3.10/site-packages/rest_framework/serializers.py", line 795, in data
    ret = super().data
  File "/usr/local/lib/python3.10/site-packages/rest_framework/serializers.py", line 249, in data
    self._data = self.to_representation(self.instance)
  File "/usr/local/lib/python3.10/site-packages/rest_framework/serializers.py", line 713, in to_representation
    return [
  File "/usr/local/lib/python3.10/site-packages/rest_framework/serializers.py", line 714, in <listcomp>
    self.child.to_representation(item) for item in iterable
  File "/app/meal_planner/serializers.py", line 18, in to_representation
    data = super().to_representation(instance)
  File "/usr/local/lib/python3.10/site-packages/rest_framework/serializers.py", line 538, in to_representation
    ret[field.field_name] = field.to_representation(attribute)
  File "/usr/local/lib/python3.10/site-packages/rest_framework/fields.py", line 1870, in to_representation
    return method(value)
  File "/app/meal_planner/serializers.py", line 15, in get_nutritional_composition
    return obj.calculate_nutritional_composition()
  File "/app/meal_planner/models.py", line 80, in calculate_nutritional_composition
    recipe = Recipe.objects.get(name=meal)  # Fetch the actual recipe object by name
  File "/usr/local/lib/python3.10/site-packages/django/db/models/manager.py", line 87, in manager_method
    return getattr(self.get_queryset(), name)(*args, **kwargs)
  File "/usr/local/lib/python3.10/site-packages/django/db/models/query.py", line 649, in get
    raise self.model.DoesNotExist(
users.models.Recipe.DoesNotExist: Recipe matching query does not exist.
Internal Server Error: /meals/meal-plans/
Traceback (most recent call last):
  File "/usr/local/lib/python3.10/site-packages/django/core/handlers/exception.py", line 55, in inner
    response = get_response(request)
  File "/usr/local/lib/python3.10/site-packages/django/core/handlers/base.py", line 197, in _get_response
    response = wrapped_callback(request, *callback_args, **callback_kwargs)
  File "/usr/local/lib/python3.10/site-packages/django/views/decorators/csrf.py", line 65, in _view_wrapper
    return view_func(request, *args, **kwargs)
  File "/usr/local/lib/python3.10/site-packages/django/views/generic/base.py", line 104, in view
    return self.dispatch(request, *args, **kwargs)
  File "/usr/local/lib/python3.10/site-packages/rest_framework/views.py", line 509, in dispatch
    response = self.handle_exception(exc)
  File "/usr/local/lib/python3.10/site-packages/rest_framework/views.py", line 469, in handle_exception
    self.raise_uncaught_exception(exc)
  File "/usr/local/lib/python3.10/site-packages/rest_framework/views.py", line 480, in raise_uncaught_exception
    raise exc
  File "/usr/local/lib/python3.10/site-packages/rest_framework/views.py", line 506, in dispatch
    response = handler(request, *args, **kwargs)
  File "/app/meal_planner/views.py", line 439, in get
    return Response(serializer.data, status=status.HTTP_200_OK)
  File "/usr/local/lib/python3.10/site-packages/rest_framework/serializers.py", line 795, in data
    ret = super().data
  File "/usr/local/lib/python3.10/site-packages/rest_framework/serializers.py", line 249, in data
    self._data = self.to_representation(self.instance)
  File "/usr/local/lib/python3.10/site-packages/rest_framework/serializers.py", line 713, in to_representation
    return [
  File "/usr/local/lib/python3.10/site-packages/rest_framework/serializers.py", line 714, in <listcomp>
    self.child.to_representation(item) for item in iterable
  File "/app/meal_planner/serializers.py", line 18, in to_representation
    data = super().to_representation(instance)
  File "/usr/local/lib/python3.10/site-packages/rest_framework/serializers.py", line 538, in to_representation
    ret[field.field_name] = field.to_representation(attribute)
  File "/usr/local/lib/python3.10/site-packages/rest_framework/fields.py", line 1870, in to_representation
    return method(value)
  File "/app/meal_planner/serializers.py", line 15, in get_nutritional_composition
    return obj.calculate_nutritional_composition()
  File "/app/meal_planner/models.py", line 80, in calculate_nutritional_composition
    recipe = Recipe.objects.get(name=meal)  # Fetch the actual recipe object by name
  File "/usr/local/lib/python3.10/site-packages/django/db/models/manager.py", line 87, in manager_method
    return getattr(self.get_queryset(), name)(*args, **kwargs)
  File "/usr/local/lib/python3.10/site-packages/django/db/models/query.py", line 649, in get
    raise self.model.DoesNotExist(
users.models.Recipe.DoesNotExist: Recipe matching query does not exist.
Internal Server Error: /meals/meal-plans/
Traceback (most recent call last):
  File "/usr/local/lib/python3.10/site-packages/django/core/handlers/exception.py", line 55, in inner
    response = get_response(request)
  File "/usr/local/lib/python3.10/site-packages/django/core/handlers/base.py", line 197, in _get_response
    response = wrapped_callback(request, *callback_args, **callback_kwargs)
  File "/usr/local/lib/python3.10/site-packages/django/views/decorators/csrf.py", line 65, in _view_wrapper
    return view_func(request, *args, **kwargs)
  File "/usr/local/lib/python3.10/site-packages/django/views/generic/base.py", line 104, in view
    return self.dispatch(request, *args, **kwargs)
  File "/usr/local/lib/python3.10/site-packages/rest_framework/views.py", line 509, in dispatch
    response = self.handle_exception(exc)
  File "/usr/local/lib/python3.10/site-packages/rest_framework/views.py", line 469, in handle_exception
    self.raise_uncaught_exception(exc)
  File "/usr/local/lib/python3.10/site-packages/rest_framework/views.py", line 480, in raise_uncaught_exception
    raise exc
  File "/usr/local/lib/python3.10/site-packages/rest_framework/views.py", line 506, in dispatch
    response = handler(request, *args, **kwargs)
  File "/app/meal_planner/views.py", line 439, in get
    return Response(serializer.data, status=status.HTTP_200_OK)
  File "/usr/local/lib/python3.10/site-packages/rest_framework/serializers.py", line 795, in data
    ret = super().data
  File "/usr/local/lib/python3.10/site-packages/rest_framework/serializers.py", line 249, in data
    self._data = self.to_representation(self.instance)
  File "/usr/local/lib/python3.10/site-packages/rest_framework/serializers.py", line 713, in to_representation
    return [
  File "/usr/local/lib/python3.10/site-packages/rest_framework/serializers.py", line 714, in <listcomp>
    self.child.to_representation(item) for item in iterable
  File "/app/meal_planner/serializers.py", line 18, in to_representation
    data = super().to_representation(instance)
  File "/usr/local/lib/python3.10/site-packages/rest_framework/serializers.py", line 538, in to_representation
    ret[field.field_name] = field.to_representation(attribute)
  File "/usr/local/lib/python3.10/site-packages/rest_framework/fields.py", line 1870, in to_representation
    return method(value)
  File "/app/meal_planner/serializers.py", line 15, in get_nutritional_composition
    return obj.calculate_nutritional_composition()
  File "/app/meal_planner/models.py", line 80, in calculate_nutritional_composition
    recipe = Recipe.objects.get(name=meal)  # Fetch the actual recipe object by name
  File "/usr/local/lib/python3.10/site-packages/django/db/models/manager.py", line 87, in manager_method
    return getattr(self.get_queryset(), name)(*args, **kwargs)
  File "/usr/local/lib/python3.10/site-packages/django/db/models/query.py", line 649, in get
    raise self.model.DoesNotExist(
users.models.Recipe.DoesNotExist: Recipe matching query does not exist.
Internal Server Error: /meals/meal-plans/
Traceback (most recent call last):
  File "/usr/local/lib/python3.10/site-packages/django/core/handlers/exception.py", line 55, in inner
    response = get_response(request)
  File "/usr/local/lib/python3.10/site-packages/django/core/handlers/base.py", line 197, in _get_response
    response = wrapped_callback(request, *callback_args, **callback_kwargs)
  File "/usr/local/lib/python3.10/site-packages/django/views/decorators/csrf.py", line 65, in _view_wrapper
    return view_func(request, *args, **kwargs)
  File "/usr/local/lib/python3.10/site-packages/django/views/generic/base.py", line 104, in view
    return self.dispatch(request, *args, **kwargs)
  File "/usr/local/lib/python3.10/site-packages/rest_framework/views.py", line 509, in dispatch
    response = self.handle_exception(exc)
  File "/usr/local/lib/python3.10/site-packages/rest_framework/views.py", line 469, in handle_exception
    self.raise_uncaught_exception(exc)
  File "/usr/local/lib/python3.10/site-packages/rest_framework/views.py", line 480, in raise_uncaught_exception
    raise exc
  File "/usr/local/lib/python3.10/site-packages/rest_framework/views.py", line 506, in dispatch
    response = handler(request, *args, **kwargs)
  File "/app/meal_planner/views.py", line 439, in get
    return Response(serializer.data, status=status.HTTP_200_OK)
  File "/usr/local/lib/python3.10/site-packages/rest_framework/serializers.py", line 795, in data
    ret = super().data
  File "/usr/local/lib/python3.10/site-packages/rest_framework/serializers.py", line 249, in data
    self._data = self.to_representation(self.instance)
  File "/usr/local/lib/python3.10/site-packages/rest_framework/serializers.py", line 713, in to_representation
    return [
  File "/usr/local/lib/python3.10/site-packages/rest_framework/serializers.py", line 714, in <listcomp>
    self.child.to_representation(item) for item in iterable
  File "/app/meal_planner/serializers.py", line 18, in to_representation
    data = super().to_representation(instance)
  File "/usr/local/lib/python3.10/site-packages/rest_framework/serializers.py", line 538, in to_representation
    ret[field.field_name] = field.to_representation(attribute)
  File "/usr/local/lib/python3.10/site-packages/rest_framework/fields.py", line 1870, in to_representation
    return method(value)
  File "/app/meal_planner/serializers.py", line 15, in get_nutritional_composition
    return obj.calculate_nutritional_composition()
  File "/app/meal_planner/models.py", line 80, in calculate_nutritional_composition
    recipe = Recipe.objects.get(name=meal)  # Fetch the actual recipe object by name
  File "/usr/local/lib/python3.10/site-packages/django/db/models/manager.py", line 87, in manager_method
    return getattr(self.get_queryset(), name)(*args, **kwargs)
  File "/usr/local/lib/python3.10/site-packages/django/db/models/query.py", line 649, in get
    raise self.model.DoesNotExist(
users.models.Recipe.DoesNotExist: Recipe matching query does not exist.
Internal Server Error: /meals/meal-plans/
Traceback (most recent call last):
  File "/usr/local/lib/python3.10/site-packages/django/core/handlers/exception.py", line 55, in inner
    response = get_response(request)
  File "/usr/local/lib/python3.10/site-packages/django/core/handlers/base.py", line 197, in _get_response
    response = wrapped_callback(request, *callback_args, **callback_kwargs)
  File "/usr/local/lib/python3.10/site-packages/django/views/decorators/csrf.py", line 65, in _view_wrapper
    return view_func(request, *args, **kwargs)
  File "/usr/local/lib/python3.10/site-packages/django/views/generic/base.py", line 104, in view
    return self.dispatch(request, *args, **kwargs)
  File "/usr/local/lib/python3.10/site-packages/rest_framework/views.py", line 509, in dispatch
    response = self.handle_exception(exc)
  File "/usr/local/lib/python3.10/site-packages/rest_framework/views.py", line 469, in handle_exception
    self.raise_uncaught_exception(exc)
  File "/usr/local/lib/python3.10/site-packages/rest_framework/views.py", line 480, in raise_uncaught_exception
    raise exc
  File "/usr/local/lib/python3.10/site-packages/rest_framework/views.py", line 506, in dispatch
    response = handler(request, *args, **kwargs)
  File "/app/meal_planner/views.py", line 439, in get
    return Response(serializer.data, status=status.HTTP_200_OK)
  File "/usr/local/lib/python3.10/site-packages/rest_framework/serializers.py", line 795, in data
    ret = super().data
  File "/usr/local/lib/python3.10/site-packages/rest_framework/serializers.py", line 249, in data
    self._data = self.to_representation(self.instance)
  File "/usr/local/lib/python3.10/site-packages/rest_framework/serializers.py", line 713, in to_representation
    return [
  File "/usr/local/lib/python3.10/site-packages/rest_framework/serializers.py", line 714, in <listcomp>
    self.child.to_representation(item) for item in iterable
  File "/app/meal_planner/serializers.py", line 18, in to_representation
    data = super().to_representation(instance)
  File "/usr/local/lib/python3.10/site-packages/rest_framework/serializers.py", line 538, in to_representation
    ret[field.field_name] = field.to_representation(attribute)
  File "/usr/local/lib/python3.10/site-packages/rest_framework/fields.py", line 1870, in to_representation
    return method(value)
  File "/app/meal_planner/serializers.py", line 15, in get_nutritional_composition
    return obj.calculate_nutritional_composition()
  File "/app/meal_planner/models.py", line 80, in calculate_nutritional_composition
    recipe = Recipe.objects.get(name=meal)  # Fetch the actual recipe object by name
  File "/usr/local/lib/python3.10/site-packages/django/db/models/manager.py", line 87, in manager_method
    return getattr(self.get_queryset(), name)(*args, **kwargs)
  File "/usr/local/lib/python3.10/site-packages/django/db/models/query.py", line 649, in get
    raise self.model.DoesNotExist(
users.models.Recipe.DoesNotExist: Recipe matching query does not exist.
Internal Server Error: /meals/meal-plans/
Traceback (most recent call last):
  File "/usr/local/lib/python3.10/site-packages/django/core/handlers/exception.py", line 55, in inner
    response = get_response(request)
  File "/usr/local/lib/python3.10/site-packages/django/core/handlers/base.py", line 197, in _get_response
    response = wrapped_callback(request, *callback_args, **callback_kwargs)
  File "/usr/local/lib/python3.10/site-packages/django/views/decorators/csrf.py", line 65, in _view_wrapper
    return view_func(request, *args, **kwargs)
  File "/usr/local/lib/python3.10/site-packages/django/views/generic/base.py", line 104, in view
    return self.dispatch(request, *args, **kwargs)
  File "/usr/local/lib/python3.10/site-packages/rest_framework/views.py", line 509, in dispatch
    response = self.handle_exception(exc)
  File "/usr/local/lib/python3.10/site-packages/rest_framework/views.py", line 469, in handle_exception
    self.raise_uncaught_exception(exc)
  File "/usr/local/lib/python3.10/site-packages/rest_framework/views.py", line 480, in raise_uncaught_exception
    raise exc
  File "/usr/local/lib/python3.10/site-packages/rest_framework/views.py", line 506, in dispatch
    response = handler(request, *args, **kwargs)
  File "/app/meal_planner/views.py", line 439, in get
    return Response(serializer.data, status=status.HTTP_200_OK)
  File "/usr/local/lib/python3.10/site-packages/rest_framework/serializers.py", line 795, in data
    ret = super().data
  File "/usr/local/lib/python3.10/site-packages/rest_framework/serializers.py", line 249, in data
    self._data = self.to_representation(self.instance)
  File "/usr/local/lib/python3.10/site-packages/rest_framework/serializers.py", line 713, in to_representation
    return [
  File "/usr/local/lib/python3.10/site-packages/rest_framework/serializers.py", line 714, in <listcomp>
    self.child.to_representation(item) for item in iterable
  File "/app/meal_planner/serializers.py", line 18, in to_representation
    data = super().to_representation(instance)
  File "/usr/local/lib/python3.10/site-packages/rest_framework/serializers.py", line 538, in to_representation
    ret[field.field_name] = field.to_representation(attribute)
  File "/usr/local/lib/python3.10/site-packages/rest_framework/fields.py", line 1870, in to_representation
    return method(value)
  File "/app/meal_planner/serializers.py", line 15, in get_nutritional_composition
    return obj.calculate_nutritional_composition()
  File "/app/meal_planner/models.py", line 78, in calculate_nutritional_composition
    logger.info(f"Trying to fetch recipe with name: {meal}")
UnboundLocalError: local variable 'meal' referenced before assignment
Internal Server Error: /meals/meal-plans/
Traceback (most recent call last):
  File "/usr/local/lib/python3.10/site-packages/django/core/handlers/exception.py", line 55, in inner
    response = get_response(request)
  File "/usr/local/lib/python3.10/site-packages/django/core/handlers/base.py", line 197, in _get_response
    response = wrapped_callback(request, *callback_args, **callback_kwargs)
  File "/usr/local/lib/python3.10/site-packages/django/views/decorators/csrf.py", line 65, in _view_wrapper
    return view_func(request, *args, **kwargs)
  File "/usr/local/lib/python3.10/site-packages/django/views/generic/base.py", line 104, in view
    return self.dispatch(request, *args, **kwargs)
  File "/usr/local/lib/python3.10/site-packages/rest_framework/views.py", line 509, in dispatch
    response = self.handle_exception(exc)
  File "/usr/local/lib/python3.10/site-packages/rest_framework/views.py", line 469, in handle_exception
    self.raise_uncaught_exception(exc)
  File "/usr/local/lib/python3.10/site-packages/rest_framework/views.py", line 480, in raise_uncaught_exception
    raise exc
  File "/usr/local/lib/python3.10/site-packages/rest_framework/views.py", line 506, in dispatch
    response = handler(request, *args, **kwargs)
  File "/app/meal_planner/views.py", line 439, in get
    return Response(serializer.data, status=status.HTTP_200_OK)
  File "/usr/local/lib/python3.10/site-packages/rest_framework/serializers.py", line 795, in data
    ret = super().data
  File "/usr/local/lib/python3.10/site-packages/rest_framework/serializers.py", line 249, in data
    self._data = self.to_representation(self.instance)
  File "/usr/local/lib/python3.10/site-packages/rest_framework/serializers.py", line 713, in to_representation
    return [
  File "/usr/local/lib/python3.10/site-packages/rest_framework/serializers.py", line 714, in <listcomp>
    self.child.to_representation(item) for item in iterable
  File "/app/meal_planner/serializers.py", line 18, in to_representation
    data = super().to_representation(instance)
  File "/usr/local/lib/python3.10/site-packages/rest_framework/serializers.py", line 538, in to_representation
    ret[field.field_name] = field.to_representation(attribute)
  File "/usr/local/lib/python3.10/site-packages/rest_framework/fields.py", line 1870, in to_representation
    return method(value)
  File "/app/meal_planner/serializers.py", line 15, in get_nutritional_composition
    return obj.calculate_nutritional_composition()
  File "/app/meal_planner/models.py", line 83, in calculate_nutritional_composition
    recipe = Recipe.objects.get(name=meal)  # Fetch the actual recipe object by name
  File "/usr/local/lib/python3.10/site-packages/django/db/models/manager.py", line 87, in manager_method
    return getattr(self.get_queryset(), name)(*args, **kwargs)
  File "/usr/local/lib/python3.10/site-packages/django/db/models/query.py", line 649, in get
    raise self.model.DoesNotExist(
users.models.Recipe.DoesNotExist: Recipe matching query does not exist.
Recipe with name '' does not exist.
Recipe with name '' does not exist.
Recipe with name '' does not exist.
Recipe with name '' does not exist.
Recipe with name '' does not exist.
Recipe with name '' does not exist.
Recipe with name '' does not exist.
Recipe with name '' does not exist.
Recipe with name '{'recipe_id': 'wvaT0151', 'name': 'Dal Tadka', 'ingredients': ['lentils', 'spices'], 'cuisine': ['indian'], 'recipe_info': 'high protein', 'vegan': True, 'vegetarian': True, 'gluten_free': True, 'pescatarian': False, 'halal': True, 'meal_type': ['lunch', 'dinner'], 'dish_type': ['protein'], 'tags': ['balanced'], 'nutrition': {'nutrition_info_id': 'xlG6KW1U', 'calories': 250, 'protein': 15, 'carbs': 0, 'fat': 8, 'fiber': 0}, 'duration': 10, 'image': None}' does not exist.
Recipe with name '{'recipe_id': 'jAwUaSm0', 'name': 'Grilled Salmon', 'ingredients': ['salmon', 'lemon', 'vegetables'], 'cuisine': ['european'], 'recipe_info': 'high protein', 'vegan': False, 'vegetarian': False, 'gluten_free': True, 'pescatarian': True, 'halal': True, 'meal_type': ['lunch', 'dinner'], 'dish_type': ['protein'], 'tags': ['high-protein'], 'nutrition': {'nutrition_info_id': 'pbthiFHQ', 'calories': 450, 'protein': 35, 'carbs': 0, 'fat': 20, 'fiber': 0}, 'duration': 10, 'image': None}' does not exist.
Recipe with name '{'name': 'Dal Tadka', 'tags': ['balanced'], 'halal': True, 'image': None, 'vegan': True, 'cuisine': ['indian'], 'duration': 10, 'dish_type': ['protein'], 'meal_type': ['lunch', 'dinner'], 'nutrition': {'fat': 8, 'carbs': 0, 'fiber': 0, 'protein': 15, 'calories': 250, 'nutrition_info_id': 'xlG6KW1U'}, 'recipe_id': 'wvaT0151', 'vegetarian': True, 'gluten_free': True, 'ingredients': ['lentils', 'spices'], 'pescatarian': False, 'recipe_info': 'high protein'}' does not exist.
Recipe with name '{'name': 'Grilled Salmon', 'tags': ['high-protein'], 'halal': True, 'image': None, 'vegan': False, 'cuisine': ['european'], 'duration': 10, 'dish_type': ['protein'], 'meal_type': ['lunch', 'dinner'], 'nutrition': {'fat': 20, 'carbs': 0, 'fiber': 0, 'protein': 35, 'calories': 450, 'nutrition_info_id': 'pbthiFHQ'}, 'recipe_id': 'jAwUaSm0', 'vegetarian': False, 'gluten_free': True, 'ingredients': ['salmon', 'lemon', 'vegetables'], 'pescatarian': True, 'recipe_info': 'high protein'}' does not exist.
Recipe with name '{'name': 'Dal Tadka', 'tags': ['balanced'], 'halal': True, 'image': None, 'vegan': True, 'cuisine': ['indian'], 'duration': 10, 'dish_type': ['protein'], 'meal_type': ['lunch', 'dinner'], 'nutrition': {'fat': 8, 'carbs': 0, 'fiber': 0, 'protein': 15, 'calories': 250, 'nutrition_info_id': 'xlG6KW1U'}, 'recipe_id': 'wvaT0151', 'vegetarian': True, 'gluten_free': True, 'ingredients': ['lentils', 'spices'], 'pescatarian': False, 'recipe_info': 'high protein'}' does not exist.
Recipe with name '{'name': 'Grilled Salmon', 'tags': ['high-protein'], 'halal': True, 'image': None, 'vegan': False, 'cuisine': ['european'], 'duration': 10, 'dish_type': ['protein'], 'meal_type': ['lunch', 'dinner'], 'nutrition': {'fat': 20, 'carbs': 0, 'fiber': 0, 'protein': 35, 'calories': 450, 'nutrition_info_id': 'pbthiFHQ'}, 'recipe_id': 'jAwUaSm0', 'vegetarian': False, 'gluten_free': True, 'ingredients': ['salmon', 'lemon', 'vegetables'], 'pescatarian': True, 'recipe_info': 'high protein'}' does not exist.
Recipe with name '{'name': 'Dal Tadka', 'tags': ['balanced'], 'halal': True, 'image': None, 'vegan': True, 'cuisine': ['indian'], 'duration': 10, 'dish_type': ['protein'], 'meal_type': ['lunch', 'dinner'], 'nutrition': {'fat': 8, 'carbs': 0, 'fiber': 0, 'protein': 15, 'calories': 250, 'nutrition_info_id': 'xlG6KW1U'}, 'recipe_id': 'wvaT0151', 'vegetarian': True, 'gluten_free': True, 'ingredients': ['lentils', 'spices'], 'pescatarian': False, 'recipe_info': 'high protein'}' does not exist.
Recipe with name '{'name': 'Grilled Salmon', 'tags': ['high-protein'], 'halal': True, 'image': None, 'vegan': False, 'cuisine': ['european'], 'duration': 10, 'dish_type': ['protein'], 'meal_type': ['lunch', 'dinner'], 'nutrition': {'fat': 20, 'carbs': 0, 'fiber': 0, 'protein': 35, 'calories': 450, 'nutrition_info_id': 'pbthiFHQ'}, 'recipe_id': 'jAwUaSm0', 'vegetarian': False, 'gluten_free': True, 'ingredients': ['salmon', 'lemon', 'vegetables'], 'pescatarian': True, 'recipe_info': 'high protein'}' does not exist.
Recipe with name '{'name': 'Dal Tadka', 'tags': ['balanced'], 'halal': True, 'image': None, 'vegan': True, 'cuisine': ['indian'], 'duration': 10, 'dish_type': ['protein'], 'meal_type': ['lunch', 'dinner'], 'nutrition': {'fat': 8, 'carbs': 0, 'fiber': 0, 'protein': 15, 'calories': 250, 'nutrition_info_id': 'xlG6KW1U'}, 'recipe_id': 'wvaT0151', 'vegetarian': True, 'gluten_free': True, 'ingredients': ['lentils', 'spices'], 'pescatarian': False, 'recipe_info': 'high protein'}' does not exist.
Recipe with name '{'name': 'Grilled Salmon', 'tags': ['high-protein'], 'halal': True, 'image': None, 'vegan': False, 'cuisine': ['european'], 'duration': 10, 'dish_type': ['protein'], 'meal_type': ['lunch', 'dinner'], 'nutrition': {'fat': 20, 'carbs': 0, 'fiber': 0, 'protein': 35, 'calories': 450, 'nutrition_info_id': 'pbthiFHQ'}, 'recipe_id': 'jAwUaSm0', 'vegetarian': False, 'gluten_free': True, 'ingredients': ['salmon', 'lemon', 'vegetables'], 'pescatarian': True, 'recipe_info': 'high protein'}' does not exist.
Recipe with name '{'recipe_id': 'wvaT0151', 'name': 'Dal Tadka', 'ingredients': ['lentils', 'spices'], 'cuisine': ['indian'], 'recipe_info': 'high protein', 'vegan': True, 'vegetarian': True, 'gluten_free': True, 'pescatarian': False, 'halal': True, 'meal_type': ['lunch', 'dinner'], 'dish_type': ['protein'], 'tags': ['balanced'], 'nutrition': {'nutrition_info_id': 'xlG6KW1U', 'calories': 250, 'protein': 15, 'carbs': 0, 'fat': 8, 'fiber': 0}, 'duration': 10, 'image': None}' does not exist.
Recipe with name '{'recipe_id': 'jAwUaSm0', 'name': 'Grilled Salmon', 'ingredients': ['salmon', 'lemon', 'vegetables'], 'cuisine': ['european'], 'recipe_info': 'high protein', 'vegan': False, 'vegetarian': False, 'gluten_free': True, 'pescatarian': True, 'halal': True, 'meal_type': ['lunch', 'dinner'], 'dish_type': ['protein'], 'tags': ['high-protein'], 'nutrition': {'nutrition_info_id': 'pbthiFHQ', 'calories': 450, 'protein': 35, 'carbs': 0, 'fat': 20, 'fiber': 0}, 'duration': 10, 'image': None}' does not exist.
Recipe with name '{'name': 'Dal Tadka', 'tags': ['balanced'], 'halal': True, 'image': None, 'vegan': True, 'cuisine': ['indian'], 'duration': 10, 'dish_type': ['protein'], 'meal_type': ['lunch', 'dinner'], 'nutrition': {'fat': 8, 'carbs': 0, 'fiber': 0, 'protein': 15, 'calories': 250, 'nutrition_info_id': 'xlG6KW1U'}, 'recipe_id': 'wvaT0151', 'vegetarian': True, 'gluten_free': True, 'ingredients': ['lentils', 'spices'], 'pescatarian': False, 'recipe_info': 'high protein'}' does not exist.
Recipe with name '{'name': 'Grilled Salmon', 'tags': ['high-protein'], 'halal': True, 'image': None, 'vegan': False, 'cuisine': ['european'], 'duration': 10, 'dish_type': ['protein'], 'meal_type': ['lunch', 'dinner'], 'nutrition': {'fat': 20, 'carbs': 0, 'fiber': 0, 'protein': 35, 'calories': 450, 'nutrition_info_id': 'pbthiFHQ'}, 'recipe_id': 'jAwUaSm0', 'vegetarian': False, 'gluten_free': True, 'ingredients': ['salmon', 'lemon', 'vegetables'], 'pescatarian': True, 'recipe_info': 'high protein'}' does not exist.
Recipe with name '{'name': 'Dal Tadka', 'tags': ['balanced'], 'halal': True, 'image': None, 'vegan': True, 'cuisine': ['indian'], 'duration': 10, 'dish_type': ['protein'], 'meal_type': ['lunch', 'dinner'], 'nutrition': {'fat': 8, 'carbs': 0, 'fiber': 0, 'protein': 15, 'calories': 250, 'nutrition_info_id': 'xlG6KW1U'}, 'recipe_id': 'wvaT0151', 'vegetarian': True, 'gluten_free': True, 'ingredients': ['lentils', 'spices'], 'pescatarian': False, 'recipe_info': 'high protein'}' does not exist.
Recipe with name '{'name': 'Grilled Salmon', 'tags': ['high-protein'], 'halal': True, 'image': None, 'vegan': False, 'cuisine': ['european'], 'duration': 10, 'dish_type': ['protein'], 'meal_type': ['lunch', 'dinner'], 'nutrition': {'fat': 20, 'carbs': 0, 'fiber': 0, 'protein': 35, 'calories': 450, 'nutrition_info_id': 'pbthiFHQ'}, 'recipe_id': 'jAwUaSm0', 'vegetarian': False, 'gluten_free': True, 'ingredients': ['salmon', 'lemon', 'vegetables'], 'pescatarian': True, 'recipe_info': 'high protein'}' does not exist.
Recipe with name '{'name': 'Dal Tadka', 'tags': ['balanced'], 'halal': True, 'image': None, 'vegan': True, 'cuisine': ['indian'], 'duration': 10, 'dish_type': ['protein'], 'meal_type': ['lunch', 'dinner'], 'nutrition': {'fat': 8, 'carbs': 0, 'fiber': 0, 'protein': 15, 'calories': 250, 'nutrition_info_id': 'xlG6KW1U'}, 'recipe_id': 'wvaT0151', 'vegetarian': True, 'gluten_free': True, 'ingredients': ['lentils', 'spices'], 'pescatarian': False, 'recipe_info': 'high protein'}' does not exist.
Recipe with name '{'name': 'Grilled Salmon', 'tags': ['high-protein'], 'halal': True, 'image': None, 'vegan': False, 'cuisine': ['european'], 'duration': 10, 'dish_type': ['protein'], 'meal_type': ['lunch', 'dinner'], 'nutrition': {'fat': 20, 'carbs': 0, 'fiber': 0, 'protein': 35, 'calories': 450, 'nutrition_info_id': 'pbthiFHQ'}, 'recipe_id': 'jAwUaSm0', 'vegetarian': False, 'gluten_free': True, 'ingredients': ['salmon', 'lemon', 'vegetables'], 'pescatarian': True, 'recipe_info': 'high protein'}' does not exist.
Recipe with name '{'name': 'Dal Tadka', 'tags': ['balanced'], 'halal': True, 'image': None, 'vegan': True, 'cuisine': ['indian'], 'duration': 10, 'dish_type': ['protein'], 'meal_type': ['lunch', 'dinner'], 'nutrition': {'fat': 8, 'carbs': 0, 'fiber': 0, 'protein': 15, 'calories': 250, 'nutrition_info_id': 'xlG6KW1U'}, 'recipe_id': 'wvaT0151', 'vegetarian': True, 'gluten_free': True, 'ingredients': ['lentils', 'spices'], 'pescatarian': False, 'recipe_info': 'high protein'}' does not exist.
Recipe with name '{'name': 'Grilled Salmon', 'tags': ['high-protein'], 'halal': True, 'image': None, 'vegan': False, 'cuisine': ['european'], 'duration': 10, 'dish_type': ['protein'], 'meal_type': ['lunch', 'dinner'], 'nutrition': {'fat': 20, 'carbs': 0, 'fiber': 0, 'protein': 35, 'calories': 450, 'nutrition_info_id': 'pbthiFHQ'}, 'recipe_id': 'jAwUaSm0', 'vegetarian': False, 'gluten_free': True, 'ingredients': ['salmon', 'lemon', 'vegetables'], 'pescatarian': True, 'recipe_info': 'high protein'}' does not exist.
Recipe with name '{'recipe_id': 'dwnuUwhF', 'name': 'Tofu Stir Fry', 'ingredients': ['tofu', 'vegetables', 'soy sauce'], 'cuisine': ['asian'], 'recipe_info': 'low calorie', 'vegan': True, 'vegetarian': True, 'gluten_free': True, 'pescatarian': False, 'halal': True, 'meal_type': ['lunch', 'dinner'], 'dish_type': ['vegetable'], 'tags': ['balanced'], 'nutrition': {'nutrition_info_id': 'yQWWsKzi', 'calories': 300, 'protein': 15, 'carbs': 0, 'fat': 10, 'fiber': 0}, 'duration': 10, 'image': None}' does not exist.
Recipe with name '{'recipe_id': 'wvaT0151', 'name': 'Dal Tadka', 'ingredients': ['lentils', 'spices'], 'cuisine': ['indian'], 'recipe_info': 'high protein', 'vegan': True, 'vegetarian': True, 'gluten_free': True, 'pescatarian': False, 'halal': True, 'meal_type': ['lunch', 'dinner'], 'dish_type': ['protein'], 'tags': ['balanced'], 'nutrition': {'nutrition_info_id': 'xlG6KW1U', 'calories': 250, 'protein': 15, 'carbs': 0, 'fat': 8, 'fiber': 0}, 'duration': 10, 'image': None}' does not exist.
Recipe with name '{'recipe_id': 'jAwUaSm0', 'name': 'Grilled Salmon', 'ingredients': ['salmon', 'lemon', 'vegetables'], 'cuisine': ['european'], 'recipe_info': 'high protein', 'vegan': False, 'vegetarian': False, 'gluten_free': True, 'pescatarian': True, 'halal': True, 'meal_type': ['lunch', 'dinner'], 'dish_type': ['protein'], 'tags': ['high-protein'], 'nutrition': {'nutrition_info_id': 'pbthiFHQ', 'calories': 450, 'protein': 35, 'carbs': 0, 'fat': 20, 'fiber': 0}, 'duration': 10, 'image': None}' does not exist.
Recipe with name '{'name': 'Dal Tadka', 'tags': ['balanced'], 'halal': True, 'image': None, 'vegan': True, 'cuisine': ['indian'], 'duration': 10, 'dish_type': ['protein'], 'meal_type': ['lunch', 'dinner'], 'nutrition': {'fat': 8, 'carbs': 0, 'fiber': 0, 'protein': 15, 'calories': 250, 'nutrition_info_id': 'xlG6KW1U'}, 'recipe_id': 'wvaT0151', 'vegetarian': True, 'gluten_free': True, 'ingredients': ['lentils', 'spices'], 'pescatarian': False, 'recipe_info': 'high protein'}' does not exist.
Recipe with name '{'name': 'Grilled Salmon', 'tags': ['high-protein'], 'halal': True, 'image': None, 'vegan': False, 'cuisine': ['european'], 'duration': 10, 'dish_type': ['protein'], 'meal_type': ['lunch', 'dinner'], 'nutrition': {'fat': 20, 'carbs': 0, 'fiber': 0, 'protein': 35, 'calories': 450, 'nutrition_info_id': 'pbthiFHQ'}, 'recipe_id': 'jAwUaSm0', 'vegetarian': False, 'gluten_free': True, 'ingredients': ['salmon', 'lemon', 'vegetables'], 'pescatarian': True, 'recipe_info': 'high protein'}' does not exist.
Recipe with name '{'name': 'Dal Tadka', 'tags': ['balanced'], 'halal': True, 'image': None, 'vegan': True, 'cuisine': ['indian'], 'duration': 10, 'dish_type': ['protein'], 'meal_type': ['lunch', 'dinner'], 'nutrition': {'fat': 8, 'carbs': 0, 'fiber': 0, 'protein': 15, 'calories': 250, 'nutrition_info_id': 'xlG6KW1U'}, 'recipe_id': 'wvaT0151', 'vegetarian': True, 'gluten_free': True, 'ingredients': ['lentils', 'spices'], 'pescatarian': False, 'recipe_info': 'high protein'}' does not exist.
Recipe with name '{'name': 'Grilled Salmon', 'tags': ['high-protein'], 'halal': True, 'image': None, 'vegan': False, 'cuisine': ['european'], 'duration': 10, 'dish_type': ['protein'], 'meal_type': ['lunch', 'dinner'], 'nutrition': {'fat': 20, 'carbs': 0, 'fiber': 0, 'protein': 35, 'calories': 450, 'nutrition_info_id': 'pbthiFHQ'}, 'recipe_id': 'jAwUaSm0', 'vegetarian': False, 'gluten_free': True, 'ingredients': ['salmon', 'lemon', 'vegetables'], 'pescatarian': True, 'recipe_info': 'high protein'}' does not exist.
Recipe with name '{'name': 'Tofu Stir Fry', 'tags': ['balanced'], 'halal': True, 'image': None, 'vegan': True, 'cuisine': ['asian'], 'duration': 10, 'dish_type': ['vegetable'], 'meal_type': ['lunch', 'dinner'], 'nutrition': {'fat': 10, 'carbs': 0, 'fiber': 0, 'protein': 15, 'calories': 300, 'nutrition_info_id': 'yQWWsKzi'}, 'recipe_id': 'dwnuUwhF', 'vegetarian': True, 'gluten_free': True, 'ingredients': ['tofu', 'vegetables', 'soy sauce'], 'pescatarian': False, 'recipe_info': 'low calorie'}' does not exist.
Recipe with name '{'name': 'Dal Tadka', 'tags': ['balanced'], 'halal': True, 'image': None, 'vegan': True, 'cuisine': ['indian'], 'duration': 10, 'dish_type': ['protein'], 'meal_type': ['lunch', 'dinner'], 'nutrition': {'fat': 8, 'carbs': 0, 'fiber': 0, 'protein': 15, 'calories': 250, 'nutrition_info_id': 'xlG6KW1U'}, 'recipe_id': 'wvaT0151', 'vegetarian': True, 'gluten_free': True, 'ingredients': ['lentils', 'spices'], 'pescatarian': False, 'recipe_info': 'high protein'}' does not exist.
Recipe with name '{'name': 'Grilled Salmon', 'tags': ['high-protein'], 'halal': True, 'image': None, 'vegan': False, 'cuisine': ['european'], 'duration': 10, 'dish_type': ['protein'], 'meal_type': ['lunch', 'dinner'], 'nutrition': {'fat': 20, 'carbs': 0, 'fiber': 0, 'protein': 35, 'calories': 450, 'nutrition_info_id': 'pbthiFHQ'}, 'recipe_id': 'jAwUaSm0', 'vegetarian': False, 'gluten_free': True, 'ingredients': ['salmon', 'lemon', 'vegetables'], 'pescatarian': True, 'recipe_info': 'high protein'}' does not exist.
Recipe with name '{'name': 'Dal Tadka', 'tags': ['balanced'], 'halal': True, 'image': None, 'vegan': True, 'cuisine': ['indian'], 'duration': 10, 'dish_type': ['protein'], 'meal_type': ['lunch', 'dinner'], 'nutrition': {'fat': 8, 'carbs': 0, 'fiber': 0, 'protein': 15, 'calories': 250, 'nutrition_info_id': 'xlG6KW1U'}, 'recipe_id': 'wvaT0151', 'vegetarian': True, 'gluten_free': True, 'ingredients': ['lentils', 'spices'], 'pescatarian': False, 'recipe_info': 'high protein'}' does not exist.
Recipe with name '{'name': 'Grilled Salmon', 'tags': ['high-protein'], 'halal': True, 'image': None, 'vegan': False, 'cuisine': ['european'], 'duration': 10, 'dish_type': ['protein'], 'meal_type': ['lunch', 'dinner'], 'nutrition': {'fat': 20, 'carbs': 0, 'fiber': 0, 'protein': 35, 'calories': 450, 'nutrition_info_id': 'pbthiFHQ'}, 'recipe_id': 'jAwUaSm0', 'vegetarian': False, 'gluten_free': True, 'ingredients': ['salmon', 'lemon', 'vegetables'], 'pescatarian': True, 'recipe_info': 'high protein'}' does not exist.
Recipe with name '{'name': 'Dal Tadka', 'tags': ['balanced'], 'halal': True, 'image': None, 'vegan': True, 'cuisine': ['indian'], 'duration': 10, 'dish_type': ['protein'], 'meal_type': ['lunch', 'dinner'], 'nutrition': {'fat': 8, 'carbs': 0, 'fiber': 0, 'protein': 15, 'calories': 250, 'nutrition_info_id': 'xlG6KW1U'}, 'recipe_id': 'wvaT0151', 'vegetarian': True, 'gluten_free': True, 'ingredients': ['lentils', 'spices'], 'pescatarian': False, 'recipe_info': 'high protein'}' does not exist.
Recipe with name '{'name': 'Grilled Salmon', 'tags': ['high-protein'], 'halal': True, 'image': None, 'vegan': False, 'cuisine': ['european'], 'duration': 10, 'dish_type': ['protein'], 'meal_type': ['lunch', 'dinner'], 'nutrition': {'fat': 20, 'carbs': 0, 'fiber': 0, 'protein': 35, 'calories': 450, 'nutrition_info_id': 'pbthiFHQ'}, 'recipe_id': 'jAwUaSm0', 'vegetarian': False, 'gluten_free': True, 'ingredients': ['salmon', 'lemon', 'vegetables'], 'pescatarian': True, 'recipe_info': 'high protein'}' does not exist.
Recipe with name '{'name': 'Tofu Stir Fry', 'tags': ['balanced'], 'halal': True, 'image': None, 'vegan': True, 'cuisine': ['asian'], 'duration': 10, 'dish_type': ['vegetable'], 'meal_type': ['lunch', 'dinner'], 'nutrition': {'fat': 10, 'carbs': 0, 'fiber': 0, 'protein': 15, 'calories': 300, 'nutrition_info_id': 'yQWWsKzi'}, 'recipe_id': 'dwnuUwhF', 'vegetarian': True, 'gluten_free': True, 'ingredients': ['tofu', 'vegetables', 'soy sauce'], 'pescatarian': False, 'recipe_info': 'low calorie'}' does not exist.
Recipe with name '{'name': 'Dal Tadka', 'tags': ['balanced'], 'halal': True, 'image': None, 'vegan': True, 'cuisine': ['indian'], 'duration': 10, 'dish_type': ['protein'], 'meal_type': ['lunch', 'dinner'], 'nutrition': {'fat': 8, 'carbs': 0, 'fiber': 0, 'protein': 15, 'calories': 250, 'nutrition_info_id': 'xlG6KW1U'}, 'recipe_id': 'wvaT0151', 'vegetarian': True, 'gluten_free': True, 'ingredients': ['lentils', 'spices'], 'pescatarian': False, 'recipe_info': 'high protein'}' does not exist.
Recipe with name '{'name': 'Grilled Salmon', 'tags': ['high-protein'], 'halal': True, 'image': None, 'vegan': False, 'cuisine': ['european'], 'duration': 10, 'dish_type': ['protein'], 'meal_type': ['lunch', 'dinner'], 'nutrition': {'fat': 20, 'carbs': 0, 'fiber': 0, 'protein': 35, 'calories': 450, 'nutrition_info_id': 'pbthiFHQ'}, 'recipe_id': 'jAwUaSm0', 'vegetarian': False, 'gluten_free': True, 'ingredients': ['salmon', 'lemon', 'vegetables'], 'pescatarian': True, 'recipe_info': 'high protein'}' does not exist.
Recipe with name '{'recipe_id': 'dwnuUwhF', 'name': 'Tofu Stir Fry', 'ingredients': ['tofu', 'vegetables', 'soy sauce'], 'cuisine': ['asian'], 'recipe_info': 'low calorie', 'vegan': True, 'vegetarian': True, 'gluten_free': True, 'pescatarian': False, 'halal': True, 'meal_type': ['lunch', 'dinner'], 'dish_type': ['vegetable'], 'tags': ['balanced'], 'nutrition': {'nutrition_info_id': 'yQWWsKzi', 'calories': 300, 'protein': 15, 'carbs': 0, 'fat': 10, 'fiber': 0}, 'duration': 10, 'image': None}' does not exist.
Recipe with name '{'recipe_id': 'wvaT0151', 'name': 'Dal Tadka', 'ingredients': ['lentils', 'spices'], 'cuisine': ['indian'], 'recipe_info': 'high protein', 'vegan': True, 'vegetarian': True, 'gluten_free': True, 'pescatarian': False, 'halal': True, 'meal_type': ['lunch', 'dinner'], 'dish_type': ['protein'], 'tags': ['balanced'], 'nutrition': {'nutrition_info_id': 'xlG6KW1U', 'calories': 250, 'protein': 15, 'carbs': 0, 'fat': 8, 'fiber': 0}, 'duration': 10, 'image': None}' does not exist.
Recipe with name '{'recipe_id': 'jAwUaSm0', 'name': 'Grilled Salmon', 'ingredients': ['salmon', 'lemon', 'vegetables'], 'cuisine': ['european'], 'recipe_info': 'high protein', 'vegan': False, 'vegetarian': False, 'gluten_free': True, 'pescatarian': True, 'halal': True, 'meal_type': ['lunch', 'dinner'], 'dish_type': ['protein'], 'tags': ['high-protein'], 'nutrition': {'nutrition_info_id': 'pbthiFHQ', 'calories': 450, 'protein': 35, 'carbs': 0, 'fat': 20, 'fiber': 0}, 'duration': 10, 'image': None}' does not exist.
Recipe with name '{'name': 'Dal Tadka', 'tags': ['balanced'], 'halal': True, 'image': None, 'vegan': True, 'cuisine': ['indian'], 'duration': 10, 'dish_type': ['protein'], 'meal_type': ['lunch', 'dinner'], 'nutrition': {'fat': 8, 'carbs': 0, 'fiber': 0, 'protein': 15, 'calories': 250, 'nutrition_info_id': 'xlG6KW1U'}, 'recipe_id': 'wvaT0151', 'vegetarian': True, 'gluten_free': True, 'ingredients': ['lentils', 'spices'], 'pescatarian': False, 'recipe_info': 'high protein'}' does not exist.
Recipe with name '{'name': 'Grilled Salmon', 'tags': ['high-protein'], 'halal': True, 'image': None, 'vegan': False, 'cuisine': ['european'], 'duration': 10, 'dish_type': ['protein'], 'meal_type': ['lunch', 'dinner'], 'nutrition': {'fat': 20, 'carbs': 0, 'fiber': 0, 'protein': 35, 'calories': 450, 'nutrition_info_id': 'pbthiFHQ'}, 'recipe_id': 'jAwUaSm0', 'vegetarian': False, 'gluten_free': True, 'ingredients': ['salmon', 'lemon', 'vegetables'], 'pescatarian': True, 'recipe_info': 'high protein'}' does not exist.
Recipe with name '{'name': 'Dal Tadka', 'tags': ['balanced'], 'halal': True, 'image': None, 'vegan': True, 'cuisine': ['indian'], 'duration': 10, 'dish_type': ['protein'], 'meal_type': ['lunch', 'dinner'], 'nutrition': {'fat': 8, 'carbs': 0, 'fiber': 0, 'protein': 15, 'calories': 250, 'nutrition_info_id': 'xlG6KW1U'}, 'recipe_id': 'wvaT0151', 'vegetarian': True, 'gluten_free': True, 'ingredients': ['lentils', 'spices'], 'pescatarian': False, 'recipe_info': 'high protein'}' does not exist.
Recipe with name '{'name': 'Grilled Salmon', 'tags': ['high-protein'], 'halal': True, 'image': None, 'vegan': False, 'cuisine': ['european'], 'duration': 10, 'dish_type': ['protein'], 'meal_type': ['lunch', 'dinner'], 'nutrition': {'fat': 20, 'carbs': 0, 'fiber': 0, 'protein': 35, 'calories': 450, 'nutrition_info_id': 'pbthiFHQ'}, 'recipe_id': 'jAwUaSm0', 'vegetarian': False, 'gluten_free': True, 'ingredients': ['salmon', 'lemon', 'vegetables'], 'pescatarian': True, 'recipe_info': 'high protein'}' does not exist.
Recipe with name '{'name': 'Tofu Stir Fry', 'tags': ['balanced'], 'halal': True, 'image': None, 'vegan': True, 'cuisine': ['asian'], 'duration': 10, 'dish_type': ['vegetable'], 'meal_type': ['lunch', 'dinner'], 'nutrition': {'fat': 10, 'carbs': 0, 'fiber': 0, 'protein': 15, 'calories': 300, 'nutrition_info_id': 'yQWWsKzi'}, 'recipe_id': 'dwnuUwhF', 'vegetarian': True, 'gluten_free': True, 'ingredients': ['tofu', 'vegetables', 'soy sauce'], 'pescatarian': False, 'recipe_info': 'low calorie'}' does not exist.
Recipe with name '{'name': 'Dal Tadka', 'tags': ['balanced'], 'halal': True, 'image': None, 'vegan': True, 'cuisine': ['indian'], 'duration': 10, 'dish_type': ['protein'], 'meal_type': ['lunch', 'dinner'], 'nutrition': {'fat': 8, 'carbs': 0, 'fiber': 0, 'protein': 15, 'calories': 250, 'nutrition_info_id': 'xlG6KW1U'}, 'recipe_id': 'wvaT0151', 'vegetarian': True, 'gluten_free': True, 'ingredients': ['lentils', 'spices'], 'pescatarian': False, 'recipe_info': 'high protein'}' does not exist.
Recipe with name '{'name': 'Grilled Salmon', 'tags': ['high-protein'], 'halal': True, 'image': None, 'vegan': False, 'cuisine': ['european'], 'duration': 10, 'dish_type': ['protein'], 'meal_type': ['lunch', 'dinner'], 'nutrition': {'fat': 20, 'carbs': 0, 'fiber': 0, 'protein': 35, 'calories': 450, 'nutrition_info_id': 'pbthiFHQ'}, 'recipe_id': 'jAwUaSm0', 'vegetarian': False, 'gluten_free': True, 'ingredients': ['salmon', 'lemon', 'vegetables'], 'pescatarian': True, 'recipe_info': 'high protein'}' does not exist.
Recipe with name '{'name': 'Tofu Stir Fry', 'tags': ['balanced'], 'halal': True, 'image': None, 'vegan': True, 'cuisine': ['asian'], 'duration': 10, 'dish_type': ['vegetable'], 'meal_type': ['lunch', 'dinner'], 'nutrition': {'fat': 10, 'carbs': 0, 'fiber': 0, 'protein': 15, 'calories': 300, 'nutrition_info_id': 'yQWWsKzi'}, 'recipe_id': 'dwnuUwhF', 'vegetarian': True, 'gluten_free': True, 'ingredients': ['tofu', 'vegetables', 'soy sauce'], 'pescatarian': False, 'recipe_info': 'low calorie'}' does not exist.
Recipe with name '{'name': 'Dal Tadka', 'tags': ['balanced'], 'halal': True, 'image': None, 'vegan': True, 'cuisine': ['indian'], 'duration': 10, 'dish_type': ['protein'], 'meal_type': ['lunch', 'dinner'], 'nutrition': {'fat': 8, 'carbs': 0, 'fiber': 0, 'protein': 15, 'calories': 250, 'nutrition_info_id': 'xlG6KW1U'}, 'recipe_id': 'wvaT0151', 'vegetarian': True, 'gluten_free': True, 'ingredients': ['lentils', 'spices'], 'pescatarian': False, 'recipe_info': 'high protein'}' does not exist.
Recipe with name '{'name': 'Grilled Salmon', 'tags': ['high-protein'], 'halal': True, 'image': None, 'vegan': False, 'cuisine': ['european'], 'duration': 10, 'dish_type': ['protein'], 'meal_type': ['lunch', 'dinner'], 'nutrition': {'fat': 20, 'carbs': 0, 'fiber': 0, 'protein': 35, 'calories': 450, 'nutrition_info_id': 'pbthiFHQ'}, 'recipe_id': 'jAwUaSm0', 'vegetarian': False, 'gluten_free': True, 'ingredients': ['salmon', 'lemon', 'vegetables'], 'pescatarian': True, 'recipe_info': 'high protein'}' does not exist.
Recipe with name '{'name': 'Dal Tadka', 'tags': ['balanced'], 'halal': True, 'image': None, 'vegan': True, 'cuisine': ['indian'], 'duration': 10, 'dish_type': ['protein'], 'meal_type': ['lunch', 'dinner'], 'nutrition': {'fat': 8, 'carbs': 0, 'fiber': 0, 'protein': 15, 'calories': 250, 'nutrition_info_id': 'xlG6KW1U'}, 'recipe_id': 'wvaT0151', 'vegetarian': True, 'gluten_free': True, 'ingredients': ['lentils', 'spices'], 'pescatarian': False, 'recipe_info': 'high protein'}' does not exist.
Recipe with name '{'name': 'Grilled Salmon', 'tags': ['high-protein'], 'halal': True, 'image': None, 'vegan': False, 'cuisine': ['european'], 'duration': 10, 'dish_type': ['protein'], 'meal_type': ['lunch', 'dinner'], 'nutrition': {'fat': 20, 'carbs': 0, 'fiber': 0, 'protein': 35, 'calories': 450, 'nutrition_info_id': 'pbthiFHQ'}, 'recipe_id': 'jAwUaSm0', 'vegetarian': False, 'gluten_free': True, 'ingredients': ['salmon', 'lemon', 'vegetables'], 'pescatarian': True, 'recipe_info': 'high protein'}' does not exist.
Recipe with name '{'name': 'Dal Tadka', 'tags': ['balanced'], 'halal': True, 'image': None, 'vegan': True, 'cuisine': ['indian'], 'duration': 10, 'dish_type': ['protein'], 'meal_type': ['lunch', 'dinner'], 'nutrition': {'fat': 8, 'carbs': 0, 'fiber': 0, 'protein': 15, 'calories': 250, 'nutrition_info_id': 'xlG6KW1U'}, 'recipe_id': 'wvaT0151', 'vegetarian': True, 'gluten_free': True, 'ingredients': ['lentils', 'spices'], 'pescatarian': False, 'recipe_info': 'high protein'}' does not exist.
Recipe with name '{'name': 'Grilled Salmon', 'tags': ['high-protein'], 'halal': True, 'image': None, 'vegan': False, 'cuisine': ['european'], 'duration': 10, 'dish_type': ['protein'], 'meal_type': ['lunch', 'dinner'], 'nutrition': {'fat': 20, 'carbs': 0, 'fiber': 0, 'protein': 35, 'calories': 450, 'nutrition_info_id': 'pbthiFHQ'}, 'recipe_id': 'jAwUaSm0', 'vegetarian': False, 'gluten_free': True, 'ingredients': ['salmon', 'lemon', 'vegetables'], 'pescatarian': True, 'recipe_info': 'high protein'}' does not exist.
Recipe with name '{'name': 'Tofu Stir Fry', 'tags': ['balanced'], 'halal': True, 'image': None, 'vegan': True, 'cuisine': ['asian'], 'duration': 10, 'dish_type': ['vegetable'], 'meal_type': ['lunch', 'dinner'], 'nutrition': {'fat': 10, 'carbs': 0, 'fiber': 0, 'protein': 15, 'calories': 300, 'nutrition_info_id': 'yQWWsKzi'}, 'recipe_id': 'dwnuUwhF', 'vegetarian': True, 'gluten_free': True, 'ingredients': ['tofu', 'vegetables', 'soy sauce'], 'pescatarian': False, 'recipe_info': 'low calorie'}' does not exist.
Recipe with name '{'name': 'Dal Tadka', 'tags': ['balanced'], 'halal': True, 'image': None, 'vegan': True, 'cuisine': ['indian'], 'duration': 10, 'dish_type': ['protein'], 'meal_type': ['lunch', 'dinner'], 'nutrition': {'fat': 8, 'carbs': 0, 'fiber': 0, 'protein': 15, 'calories': 250, 'nutrition_info_id': 'xlG6KW1U'}, 'recipe_id': 'wvaT0151', 'vegetarian': True, 'gluten_free': True, 'ingredients': ['lentils', 'spices'], 'pescatarian': False, 'recipe_info': 'high protein'}' does not exist.
Recipe with name '{'name': 'Grilled Salmon', 'tags': ['high-protein'], 'halal': True, 'image': None, 'vegan': False, 'cuisine': ['european'], 'duration': 10, 'dish_type': ['protein'], 'meal_type': ['lunch', 'dinner'], 'nutrition': {'fat': 20, 'carbs': 0, 'fiber': 0, 'protein': 35, 'calories': 450, 'nutrition_info_id': 'pbthiFHQ'}, 'recipe_id': 'jAwUaSm0', 'vegetarian': False, 'gluten_free': True, 'ingredients': ['salmon', 'lemon', 'vegetables'], 'pescatarian': True, 'recipe_info': 'high protein'}' does not exist.
Recipe with name '{'name': 'Tofu Stir Fry', 'tags': ['balanced'], 'halal': True, 'image': None, 'vegan': True, 'cuisine': ['asian'], 'duration': 10, 'dish_type': ['vegetable'], 'meal_type': ['lunch', 'dinner'], 'nutrition': {'fat': 10, 'carbs': 0, 'fiber': 0, 'protein': 15, 'calories': 300, 'nutrition_info_id': 'yQWWsKzi'}, 'recipe_id': 'dwnuUwhF', 'vegetarian': True, 'gluten_free': True, 'ingredients': ['tofu', 'vegetables', 'soy sauce'], 'pescatarian': False, 'recipe_info': 'low calorie'}' does not exist.
Recipe with name '{'name': 'Dal Tadka', 'tags': ['balanced'], 'halal': True, 'image': None, 'vegan': True, 'cuisine': ['indian'], 'duration': 10, 'dish_type': ['protein'], 'meal_type': ['lunch', 'dinner'], 'nutrition': {'fat': 8, 'carbs': 0, 'fiber': 0, 'protein': 15, 'calories': 250, 'nutrition_info_id': 'xlG6KW1U'}, 'recipe_id': 'wvaT0151', 'vegetarian': True, 'gluten_free': True, 'ingredients': ['lentils', 'spices'], 'pescatarian': False, 'recipe_info': 'high protein'}' does not exist.
Recipe with name '{'name': 'Grilled Salmon', 'tags': ['high-protein'], 'halal': True, 'image': None, 'vegan': False, 'cuisine': ['european'], 'duration': 10, 'dish_type': ['protein'], 'meal_type': ['lunch', 'dinner'], 'nutrition': {'fat': 20, 'carbs': 0, 'fiber': 0, 'protein': 35, 'calories': 450, 'nutrition_info_id': 'pbthiFHQ'}, 'recipe_id': 'jAwUaSm0', 'vegetarian': False, 'gluten_free': True, 'ingredients': ['salmon', 'lemon', 'vegetables'], 'pescatarian': True, 'recipe_info': 'high protein'}' does not exist.
Recipe with name '{'recipe_id': 'dwnuUwhF', 'name': 'Tofu Stir Fry', 'ingredients': ['tofu', 'vegetables', 'soy sauce'], 'cuisine': ['asian'], 'recipe_info': 'low calorie', 'vegan': True, 'vegetarian': True, 'gluten_free': True, 'pescatarian': False, 'halal': True, 'meal_type': ['lunch', 'dinner'], 'dish_type': ['vegetable'], 'tags': ['balanced'], 'nutrition': {'nutrition_info_id': 'yQWWsKzi', 'calories': 300, 'protein': 15, 'carbs': 0, 'fat': 10, 'fiber': 0}, 'duration': 10, 'image': None}' does not exist.
Recipe with name '{'name': 'Dal Tadka', 'tags': ['balanced'], 'halal': True, 'image': None, 'vegan': True, 'cuisine': ['indian'], 'duration': 10, 'dish_type': ['protein'], 'meal_type': ['lunch', 'dinner'], 'nutrition': {'fat': 8, 'carbs': 0, 'fiber': 0, 'protein': 15, 'calories': 250, 'nutrition_info_id': 'xlG6KW1U'}, 'recipe_id': 'wvaT0151', 'vegetarian': True, 'gluten_free': True, 'ingredients': ['lentils', 'spices'], 'pescatarian': False, 'recipe_info': 'high protein'}' does not exist.
Recipe with name '{'name': 'Grilled Salmon', 'tags': ['high-protein'], 'halal': True, 'image': None, 'vegan': False, 'cuisine': ['european'], 'duration': 10, 'dish_type': ['protein'], 'meal_type': ['lunch', 'dinner'], 'nutrition': {'fat': 20, 'carbs': 0, 'fiber': 0, 'protein': 35, 'calories': 450, 'nutrition_info_id': 'pbthiFHQ'}, 'recipe_id': 'jAwUaSm0', 'vegetarian': False, 'gluten_free': True, 'ingredients': ['salmon', 'lemon', 'vegetables'], 'pescatarian': True, 'recipe_info': 'high protein'}' does not exist.
Recipe with name '{'name': 'Dal Tadka', 'tags': ['balanced'], 'halal': True, 'image': None, 'vegan': True, 'cuisine': ['indian'], 'duration': 10, 'dish_type': ['protein'], 'meal_type': ['lunch', 'dinner'], 'nutrition': {'fat': 8, 'carbs': 0, 'fiber': 0, 'protein': 15, 'calories': 250, 'nutrition_info_id': 'xlG6KW1U'}, 'recipe_id': 'wvaT0151', 'vegetarian': True, 'gluten_free': True, 'ingredients': ['lentils', 'spices'], 'pescatarian': False, 'recipe_info': 'high protein'}' does not exist.
Recipe with name '{'name': 'Grilled Salmon', 'tags': ['high-protein'], 'halal': True, 'image': None, 'vegan': False, 'cuisine': ['european'], 'duration': 10, 'dish_type': ['protein'], 'meal_type': ['lunch', 'dinner'], 'nutrition': {'fat': 20, 'carbs': 0, 'fiber': 0, 'protein': 35, 'calories': 450, 'nutrition_info_id': 'pbthiFHQ'}, 'recipe_id': 'jAwUaSm0', 'vegetarian': False, 'gluten_free': True, 'ingredients': ['salmon', 'lemon', 'vegetables'], 'pescatarian': True, 'recipe_info': 'high protein'}' does not exist.
Recipe with name '{'name': 'Tofu Stir Fry', 'tags': ['balanced'], 'halal': True, 'image': None, 'vegan': True, 'cuisine': ['asian'], 'duration': 10, 'dish_type': ['vegetable'], 'meal_type': ['lunch', 'dinner'], 'nutrition': {'fat': 10, 'carbs': 0, 'fiber': 0, 'protein': 15, 'calories': 300, 'nutrition_info_id': 'yQWWsKzi'}, 'recipe_id': 'dwnuUwhF', 'vegetarian': True, 'gluten_free': True, 'ingredients': ['tofu', 'vegetables', 'soy sauce'], 'pescatarian': False, 'recipe_info': 'low calorie'}' does not exist.
Recipe with name '{'name': 'Dal Tadka', 'tags': ['balanced'], 'halal': True, 'image': None, 'vegan': True, 'cuisine': ['indian'], 'duration': 10, 'dish_type': ['protein'], 'meal_type': ['lunch', 'dinner'], 'nutrition': {'fat': 8, 'carbs': 0, 'fiber': 0, 'protein': 15, 'calories': 250, 'nutrition_info_id': 'xlG6KW1U'}, 'recipe_id': 'wvaT0151', 'vegetarian': True, 'gluten_free': True, 'ingredients': ['lentils', 'spices'], 'pescatarian': False, 'recipe_info': 'high protein'}' does not exist.
Recipe with name '{'name': 'Grilled Salmon', 'tags': ['high-protein'], 'halal': True, 'image': None, 'vegan': False, 'cuisine': ['european'], 'duration': 10, 'dish_type': ['protein'], 'meal_type': ['lunch', 'dinner'], 'nutrition': {'fat': 20, 'carbs': 0, 'fiber': 0, 'protein': 35, 'calories': 450, 'nutrition_info_id': 'pbthiFHQ'}, 'recipe_id': 'jAwUaSm0', 'vegetarian': False, 'gluten_free': True, 'ingredients': ['salmon', 'lemon', 'vegetables'], 'pescatarian': True, 'recipe_info': 'high protein'}' does not exist.
Recipe with name '{'name': 'Tofu Stir Fry', 'tags': ['balanced'], 'halal': True, 'image': None, 'vegan': True, 'cuisine': ['asian'], 'duration': 10, 'dish_type': ['vegetable'], 'meal_type': ['lunch', 'dinner'], 'nutrition': {'fat': 10, 'carbs': 0, 'fiber': 0, 'protein': 15, 'calories': 300, 'nutrition_info_id': 'yQWWsKzi'}, 'recipe_id': 'dwnuUwhF', 'vegetarian': True, 'gluten_free': True, 'ingredients': ['tofu', 'vegetables', 'soy sauce'], 'pescatarian': False, 'recipe_info': 'low calorie'}' does not exist.
Recipe with name '{'name': 'Dal Tadka', 'tags': ['balanced'], 'halal': True, 'image': None, 'vegan': True, 'cuisine': ['indian'], 'duration': 10, 'dish_type': ['protein'], 'meal_type': ['lunch', 'dinner'], 'nutrition': {'fat': 8, 'carbs': 0, 'fiber': 0, 'protein': 15, 'calories': 250, 'nutrition_info_id': 'xlG6KW1U'}, 'recipe_id': 'wvaT0151', 'vegetarian': True, 'gluten_free': True, 'ingredients': ['lentils', 'spices'], 'pescatarian': False, 'recipe_info': 'high protein'}' does not exist.
Recipe with name '{'name': 'Grilled Salmon', 'tags': ['high-protein'], 'halal': True, 'image': None, 'vegan': False, 'cuisine': ['european'], 'duration': 10, 'dish_type': ['protein'], 'meal_type': ['lunch', 'dinner'], 'nutrition': {'fat': 20, 'carbs': 0, 'fiber': 0, 'protein': 35, 'calories': 450, 'nutrition_info_id': 'pbthiFHQ'}, 'recipe_id': 'jAwUaSm0', 'vegetarian': False, 'gluten_free': True, 'ingredients': ['salmon', 'lemon', 'vegetables'], 'pescatarian': True, 'recipe_info': 'high protein'}' does not exist.
Recipe with name '{'name': 'Tofu Stir Fry', 'tags': ['balanced'], 'halal': True, 'image': None, 'vegan': True, 'cuisine': ['asian'], 'duration': 10, 'dish_type': ['vegetable'], 'meal_type': ['lunch', 'dinner'], 'nutrition': {'fat': 10, 'carbs': 0, 'fiber': 0, 'protein': 15, 'calories': 300, 'nutrition_info_id': 'yQWWsKzi'}, 'recipe_id': 'dwnuUwhF', 'vegetarian': True, 'gluten_free': True, 'ingredients': ['tofu', 'vegetables', 'soy sauce'], 'pescatarian': False, 'recipe_info': 'low calorie'}' does not exist.
Recipe with name '{'name': 'Dal Tadka', 'tags': ['balanced'], 'halal': True, 'image': None, 'vegan': True, 'cuisine': ['indian'], 'duration': 10, 'dish_type': ['protein'], 'meal_type': ['lunch', 'dinner'], 'nutrition': {'fat': 8, 'carbs': 0, 'fiber': 0, 'protein': 15, 'calories': 250, 'nutrition_info_id': 'xlG6KW1U'}, 'recipe_id': 'wvaT0151', 'vegetarian': True, 'gluten_free': True, 'ingredients': ['lentils', 'spices'], 'pescatarian': False, 'recipe_info': 'high protein'}' does not exist.
Recipe with name '{'name': 'Grilled Salmon', 'tags': ['high-protein'], 'halal': True, 'image': None, 'vegan': False, 'cuisine': ['european'], 'duration': 10, 'dish_type': ['protein'], 'meal_type': ['lunch', 'dinner'], 'nutrition': {'fat': 20, 'carbs': 0, 'fiber': 0, 'protein': 35, 'calories': 450, 'nutrition_info_id': 'pbthiFHQ'}, 'recipe_id': 'jAwUaSm0', 'vegetarian': False, 'gluten_free': True, 'ingredients': ['salmon', 'lemon', 'vegetables'], 'pescatarian': True, 'recipe_info': 'high protein'}' does not exist.
Recipe with name '{'name': 'Dal Tadka', 'tags': ['balanced'], 'halal': True, 'image': None, 'vegan': True, 'cuisine': ['indian'], 'duration': 10, 'dish_type': ['protein'], 'meal_type': ['lunch', 'dinner'], 'nutrition': {'fat': 8, 'carbs': 0, 'fiber': 0, 'protein': 15, 'calories': 250, 'nutrition_info_id': 'xlG6KW1U'}, 'recipe_id': 'wvaT0151', 'vegetarian': True, 'gluten_free': True, 'ingredients': ['lentils', 'spices'], 'pescatarian': False, 'recipe_info': 'high protein'}' does not exist.
Recipe with name '{'name': 'Grilled Salmon', 'tags': ['high-protein'], 'halal': True, 'image': None, 'vegan': False, 'cuisine': ['european'], 'duration': 10, 'dish_type': ['protein'], 'meal_type': ['lunch', 'dinner'], 'nutrition': {'fat': 20, 'carbs': 0, 'fiber': 0, 'protein': 35, 'calories': 450, 'nutrition_info_id': 'pbthiFHQ'}, 'recipe_id': 'jAwUaSm0', 'vegetarian': False, 'gluten_free': True, 'ingredients': ['salmon', 'lemon', 'vegetables'], 'pescatarian': True, 'recipe_info': 'high protein'}' does not exist.
Recipe with name '{'name': 'Tofu Stir Fry', 'tags': ['balanced'], 'halal': True, 'image': None, 'vegan': True, 'cuisine': ['asian'], 'duration': 10, 'dish_type': ['vegetable'], 'meal_type': ['lunch', 'dinner'], 'nutrition': {'fat': 10, 'carbs': 0, 'fiber': 0, 'protein': 15, 'calories': 300, 'nutrition_info_id': 'yQWWsKzi'}, 'recipe_id': 'dwnuUwhF', 'vegetarian': True, 'gluten_free': True, 'ingredients': ['tofu', 'vegetables', 'soy sauce'], 'pescatarian': False, 'recipe_info': 'low calorie'}' does not exist.
Recipe with name '{'name': 'Dal Tadka', 'tags': ['balanced'], 'halal': True, 'image': None, 'vegan': True, 'cuisine': ['indian'], 'duration': 10, 'dish_type': ['protein'], 'meal_type': ['lunch', 'dinner'], 'nutrition': {'fat': 8, 'carbs': 0, 'fiber': 0, 'protein': 15, 'calories': 250, 'nutrition_info_id': 'xlG6KW1U'}, 'recipe_id': 'wvaT0151', 'vegetarian': True, 'gluten_free': True, 'ingredients': ['lentils', 'spices'], 'pescatarian': False, 'recipe_info': 'high protein'}' does not exist.
Recipe with name '{'name': 'Grilled Salmon', 'tags': ['high-protein'], 'halal': True, 'image': None, 'vegan': False, 'cuisine': ['european'], 'duration': 10, 'dish_type': ['protein'], 'meal_type': ['lunch', 'dinner'], 'nutrition': {'fat': 20, 'carbs': 0, 'fiber': 0, 'protein': 35, 'calories': 450, 'nutrition_info_id': 'pbthiFHQ'}, 'recipe_id': 'jAwUaSm0', 'vegetarian': False, 'gluten_free': True, 'ingredients': ['salmon', 'lemon', 'vegetables'], 'pescatarian': True, 'recipe_info': 'high protein'}' does not exist.
Recipe with name '{'name': 'Tofu Stir Fry', 'tags': ['balanced'], 'halal': True, 'image': None, 'vegan': True, 'cuisine': ['asian'], 'duration': 10, 'dish_type': ['vegetable'], 'meal_type': ['lunch', 'dinner'], 'nutrition': {'fat': 10, 'carbs': 0, 'fiber': 0, 'protein': 15, 'calories': 300, 'nutrition_info_id': 'yQWWsKzi'}, 'recipe_id': 'dwnuUwhF', 'vegetarian': True, 'gluten_free': True, 'ingredients': ['tofu', 'vegetables', 'soy sauce'], 'pescatarian': False, 'recipe_info': 'low calorie'}' does not exist.
Recipe with name '{'name': 'Dal Tadka', 'tags': ['balanced'], 'halal': True, 'image': None, 'vegan': True, 'cuisine': ['indian'], 'duration': 10, 'dish_type': ['protein'], 'meal_type': ['lunch', 'dinner'], 'nutrition': {'fat': 8, 'carbs': 0, 'fiber': 0, 'protein': 15, 'calories': 250, 'nutrition_info_id': 'xlG6KW1U'}, 'recipe_id': 'wvaT0151', 'vegetarian': True, 'gluten_free': True, 'ingredients': ['lentils', 'spices'], 'pescatarian': False, 'recipe_info': 'high protein'}' does not exist.
Recipe with name '{'name': 'Grilled Salmon', 'tags': ['high-protein'], 'halal': True, 'image': None, 'vegan': False, 'cuisine': ['european'], 'duration': 10, 'dish_type': ['protein'], 'meal_type': ['lunch', 'dinner'], 'nutrition': {'fat': 20, 'carbs': 0, 'fiber': 0, 'protein': 35, 'calories': 450, 'nutrition_info_id': 'pbthiFHQ'}, 'recipe_id': 'jAwUaSm0', 'vegetarian': False, 'gluten_free': True, 'ingredients': ['salmon', 'lemon', 'vegetables'], 'pescatarian': True, 'recipe_info': 'high protein'}' does not exist.
Recipe with name '{'name': 'Tofu Stir Fry', 'tags': ['balanced'], 'halal': True, 'image': None, 'vegan': True, 'cuisine': ['asian'], 'duration': 10, 'dish_type': ['vegetable'], 'meal_type': ['lunch', 'dinner'], 'nutrition': {'fat': 10, 'carbs': 0, 'fiber': 0, 'protein': 15, 'calories': 300, 'nutrition_info_id': 'yQWWsKzi'}, 'recipe_id': 'dwnuUwhF', 'vegetarian': True, 'gluten_free': True, 'ingredients': ['tofu', 'vegetables', 'soy sauce'], 'pescatarian': False, 'recipe_info': 'low calorie'}' does not exist.
Recipe with name '{'recipe_id': 'dwnuUwhF', 'name': 'Tofu Stir Fry', 'ingredients': ['tofu', 'vegetables', 'soy sauce'], 'cuisine': ['asian'], 'recipe_info': 'low calorie', 'vegan': True, 'vegetarian': True, 'gluten_free': True, 'pescatarian': False, 'halal': True, 'meal_type': ['lunch', 'dinner'], 'dish_type': ['vegetable'], 'tags': ['balanced'], 'nutrition': {'nutrition_info_id': 'yQWWsKzi', 'calories': 300, 'protein': 15, 'carbs': 0, 'fat': 10, 'fiber': 0}, 'duration': 10, 'image': None}' does not exist.
Recipe with name '{'name': 'Dal Tadka', 'tags': ['balanced'], 'halal': True, 'image': None, 'vegan': True, 'cuisine': ['indian'], 'duration': 10, 'dish_type': ['protein'], 'meal_type': ['lunch', 'dinner'], 'nutrition': {'fat': 8, 'carbs': 0, 'fiber': 0, 'protein': 15, 'calories': 250, 'nutrition_info_id': 'xlG6KW1U'}, 'recipe_id': 'wvaT0151', 'vegetarian': True, 'gluten_free': True, 'ingredients': ['lentils', 'spices'], 'pescatarian': False, 'recipe_info': 'high protein'}' does not exist.
Recipe with name '{'name': 'Grilled Salmon', 'tags': ['high-protein'], 'halal': True, 'image': None, 'vegan': False, 'cuisine': ['european'], 'duration': 10, 'dish_type': ['protein'], 'meal_type': ['lunch', 'dinner'], 'nutrition': {'fat': 20, 'carbs': 0, 'fiber': 0, 'protein': 35, 'calories': 450, 'nutrition_info_id': 'pbthiFHQ'}, 'recipe_id': 'jAwUaSm0', 'vegetarian': False, 'gluten_free': True, 'ingredients': ['salmon', 'lemon', 'vegetables'], 'pescatarian': True, 'recipe_info': 'high protein'}' does not exist.
Recipe with name '{'name': 'Dal Tadka', 'tags': ['balanced'], 'halal': True, 'image': None, 'vegan': True, 'cuisine': ['indian'], 'duration': 10, 'dish_type': ['protein'], 'meal_type': ['lunch', 'dinner'], 'nutrition': {'fat': 8, 'carbs': 0, 'fiber': 0, 'protein': 15, 'calories': 250, 'nutrition_info_id': 'xlG6KW1U'}, 'recipe_id': 'wvaT0151', 'vegetarian': True, 'gluten_free': True, 'ingredients': ['lentils', 'spices'], 'pescatarian': False, 'recipe_info': 'high protein'}' does not exist.
Recipe with name '{'name': 'Grilled Salmon', 'tags': ['high-protein'], 'halal': True, 'image': None, 'vegan': False, 'cuisine': ['european'], 'duration': 10, 'dish_type': ['protein'], 'meal_type': ['lunch', 'dinner'], 'nutrition': {'fat': 20, 'carbs': 0, 'fiber': 0, 'protein': 35, 'calories': 450, 'nutrition_info_id': 'pbthiFHQ'}, 'recipe_id': 'jAwUaSm0', 'vegetarian': False, 'gluten_free': True, 'ingredients': ['salmon', 'lemon', 'vegetables'], 'pescatarian': True, 'recipe_info': 'high protein'}' does not exist.
Recipe with name '{'name': 'Tofu Stir Fry', 'tags': ['balanced'], 'halal': True, 'image': None, 'vegan': True, 'cuisine': ['asian'], 'duration': 10, 'dish_type': ['vegetable'], 'meal_type': ['lunch', 'dinner'], 'nutrition': {'fat': 10, 'carbs': 0, 'fiber': 0, 'protein': 15, 'calories': 300, 'nutrition_info_id': 'yQWWsKzi'}, 'recipe_id': 'dwnuUwhF', 'vegetarian': True, 'gluten_free': True, 'ingredients': ['tofu', 'vegetables', 'soy sauce'], 'pescatarian': False, 'recipe_info': 'low calorie'}' does not exist.
Recipe with name '{'name': 'Dal Tadka', 'tags': ['balanced'], 'halal': True, 'image': None, 'vegan': True, 'cuisine': ['indian'], 'duration': 10, 'dish_type': ['protein'], 'meal_type': ['lunch', 'dinner'], 'nutrition': {'fat': 8, 'carbs': 0, 'fiber': 0, 'protein': 15, 'calories': 250, 'nutrition_info_id': 'xlG6KW1U'}, 'recipe_id': 'wvaT0151', 'vegetarian': True, 'gluten_free': True, 'ingredients': ['lentils', 'spices'], 'pescatarian': False, 'recipe_info': 'high protein'}' does not exist.
Recipe with name '{'name': 'Grilled Salmon', 'tags': ['high-protein'], 'halal': True, 'image': None, 'vegan': False, 'cuisine': ['european'], 'duration': 10, 'dish_type': ['protein'], 'meal_type': ['lunch', 'dinner'], 'nutrition': {'fat': 20, 'carbs': 0, 'fiber': 0, 'protein': 35, 'calories': 450, 'nutrition_info_id': 'pbthiFHQ'}, 'recipe_id': 'jAwUaSm0', 'vegetarian': False, 'gluten_free': True, 'ingredients': ['salmon', 'lemon', 'vegetables'], 'pescatarian': True, 'recipe_info': 'high protein'}' does not exist.
Recipe with name '{'name': 'Tofu Stir Fry', 'tags': ['balanced'], 'halal': True, 'image': None, 'vegan': True, 'cuisine': ['asian'], 'duration': 10, 'dish_type': ['vegetable'], 'meal_type': ['lunch', 'dinner'], 'nutrition': {'fat': 10, 'carbs': 0, 'fiber': 0, 'protein': 15, 'calories': 300, 'nutrition_info_id': 'yQWWsKzi'}, 'recipe_id': 'dwnuUwhF', 'vegetarian': True, 'gluten_free': True, 'ingredients': ['tofu', 'vegetables', 'soy sauce'], 'pescatarian': False, 'recipe_info': 'low calorie'}' does not exist.
Recipe with name '{'name': 'Dal Tadka', 'tags': ['balanced'], 'halal': True, 'image': None, 'vegan': True, 'cuisine': ['indian'], 'duration': 10, 'dish_type': ['protein'], 'meal_type': ['lunch', 'dinner'], 'nutrition': {'fat': 8, 'carbs': 0, 'fiber': 0, 'protein': 15, 'calories': 250, 'nutrition_info_id': 'xlG6KW1U'}, 'recipe_id': 'wvaT0151', 'vegetarian': True, 'gluten_free': True, 'ingredients': ['lentils', 'spices'], 'pescatarian': False, 'recipe_info': 'high protein'}' does not exist.
Recipe with name '{'name': 'Grilled Salmon', 'tags': ['high-protein'], 'halal': True, 'image': None, 'vegan': False, 'cuisine': ['european'], 'duration': 10, 'dish_type': ['protein'], 'meal_type': ['lunch', 'dinner'], 'nutrition': {'fat': 20, 'carbs': 0, 'fiber': 0, 'protein': 35, 'calories': 450, 'nutrition_info_id': 'pbthiFHQ'}, 'recipe_id': 'jAwUaSm0', 'vegetarian': False, 'gluten_free': True, 'ingredients': ['salmon', 'lemon', 'vegetables'], 'pescatarian': True, 'recipe_info': 'high protein'}' does not exist.
Recipe with name '{'name': 'Tofu Stir Fry', 'tags': ['balanced'], 'halal': True, 'image': None, 'vegan': True, 'cuisine': ['asian'], 'duration': 10, 'dish_type': ['vegetable'], 'meal_type': ['lunch', 'dinner'], 'nutrition': {'fat': 10, 'carbs': 0, 'fiber': 0, 'protein': 15, 'calories': 300, 'nutrition_info_id': 'yQWWsKzi'}, 'recipe_id': 'dwnuUwhF', 'vegetarian': True, 'gluten_free': True, 'ingredients': ['tofu', 'vegetables', 'soy sauce'], 'pescatarian': False, 'recipe_info': 'low calorie'}' does not exist.
Recipe with name '{'name': 'Tofu Stir Fry', 'tags': ['balanced'], 'halal': True, 'image': None, 'vegan': True, 'cuisine': ['asian'], 'duration': 10, 'dish_type': ['vegetable'], 'meal_type': ['lunch', 'dinner'], 'nutrition': {'fat': 10, 'carbs': 0, 'fiber': 0, 'protein': 15, 'calories': 300, 'nutrition_info_id': 'yQWWsKzi'}, 'recipe_id': 'dwnuUwhF', 'vegetarian': True, 'gluten_free': True, 'ingredients': ['tofu', 'vegetables', 'soy sauce'], 'pescatarian': False, 'recipe_info': 'low calorie'}' does not exist.
Internal Server Error: /register/
Traceback (most recent call last):
  File "/usr/local/lib/python3.10/site-packages/django/db/backends/utils.py", line 105, in _execute
    return self.cursor.execute(sql, params)
psycopg2.errors.UndefinedColumn: column "age" of relation "users_user" does not exist
LINE 1: ... "is_active", "date_joined", "username", "email", "age", "ge...
                                                             ^


The above exception was the direct cause of the following exception:

Traceback (most recent call last):
  File "/app/users/views.py", line 46, in create
    user = serializer.save()
  File "/usr/local/lib/python3.10/site-packages/rest_framework/serializers.py", line 208, in save
    self.instance = self.create(validated_data)
  File "/app/users/serializers.py", line 26, in create
    validated_data.pop('password2')
  File "/app/users/models.py", line 29, in create_user
    return self._create_user(email, password, **extra_fields)
  File "/app/users/models.py", line 22, in _create_user
    user.save(using=self._db)
  File "/usr/local/lib/python3.10/site-packages/django/contrib/auth/base_user.py", line 62, in save
    super().save(*args, **kwargs)
  File "/usr/local/lib/python3.10/site-packages/django/db/models/base.py", line 891, in save
    self.save_base(
  File "/usr/local/lib/python3.10/site-packages/django/db/models/base.py", line 997, in save_base
    updated = self._save_table(
  File "/usr/local/lib/python3.10/site-packages/django/db/models/base.py", line 1160, in _save_table
    results = self._do_insert(
  File "/usr/local/lib/python3.10/site-packages/django/db/models/base.py", line 1201, in _do_insert
    return manager._insert(
  File "/usr/local/lib/python3.10/site-packages/django/db/models/manager.py", line 87, in manager_method
    return getattr(self.get_queryset(), name)(*args, **kwargs)
  File "/usr/local/lib/python3.10/site-packages/django/db/models/query.py", line 1847, in _insert
    return query.get_compiler(using=using).execute_sql(returning_fields)
  File "/usr/local/lib/python3.10/site-packages/django/db/models/sql/compiler.py", line 1836, in execute_sql
    cursor.execute(sql, params)
  File "/usr/local/lib/python3.10/site-packages/django/db/backends/utils.py", line 122, in execute
    return super().execute(sql, params)
  File "/usr/local/lib/python3.10/site-packages/django/db/backends/utils.py", line 79, in execute
    return self._execute_with_wrappers(
  File "/usr/local/lib/python3.10/site-packages/django/db/backends/utils.py", line 92, in _execute_with_wrappers
    return executor(sql, params, many, context)
  File "/usr/local/lib/python3.10/site-packages/django/db/backends/utils.py", line 100, in _execute
    with self.db.wrap_database_errors:
  File "/usr/local/lib/python3.10/site-packages/django/db/utils.py", line 91, in __exit__
    raise dj_exc_value.with_traceback(traceback) from exc_value
  File "/usr/local/lib/python3.10/site-packages/django/db/backends/utils.py", line 105, in _execute
    return self.cursor.execute(sql, params)
django.db.utils.ProgrammingError: column "age" of relation "users_user" does not exist
LINE 1: ... "is_active", "date_joined", "username", "email", "age", "ge...
                                                             ^


During handling of the above exception, another exception occurred:

Traceback (most recent call last):
  File "/usr/local/lib/python3.10/site-packages/django/core/handlers/exception.py", line 55, in inner
    response = get_response(request)
  File "/usr/local/lib/python3.10/site-packages/django/core/handlers/base.py", line 197, in _get_response
    response = wrapped_callback(request, *callback_args, **callback_kwargs)
  File "/usr/local/lib/python3.10/site-packages/django/views/decorators/csrf.py", line 65, in _view_wrapper
    return view_func(request, *args, **kwargs)
  File "/usr/local/lib/python3.10/site-packages/django/views/generic/base.py", line 104, in view
    return self.dispatch(request, *args, **kwargs)
  File "/usr/local/lib/python3.10/site-packages/rest_framework/views.py", line 509, in dispatch
    response = self.handle_exception(exc)
  File "/usr/local/lib/python3.10/site-packages/rest_framework/views.py", line 469, in handle_exception
    self.raise_uncaught_exception(exc)
  File "/usr/local/lib/python3.10/site-packages/rest_framework/views.py", line 480, in raise_uncaught_exception
    raise exc
  File "/usr/local/lib/python3.10/site-packages/rest_framework/views.py", line 506, in dispatch
    response = handler(request, *args, **kwargs)
  File "/usr/local/lib/python3.10/site-packages/rest_framework/generics.py", line 194, in post
    return self.create(request, *args, **kwargs)
  File "/app/users/views.py", line 76, in create
    logger.error(f"Registration failed: {str(e)}")
NameError: name 'logger' is not defined
Registration failed: name 'date' is not defined
Internal Server Error: /register/
Recommendation generation failed: 'cuisine_preference'
Traceback (most recent call last):
  File "/app/meal_planner/views.py", line 58, in post
    meal_plans = recommender.get_recommendations(user_profile)
  File "/app/meal_planner/ai_model.py", line 297, in get_recommendations
    content_recs = self.content_recommender.get_recommendations(user_profile)
  File "/app/meal_planner/ai_model.py", line 35, in get_recommendations
    f"{' '.join(user_profile['dietary_preferences'])} {user_profile['health_goals']} {user_profile['cuisine_preference']} "
KeyError: 'cuisine_preference'
Internal Server Error: /meals/meal-plans/generate/
Recommendation generation failed: 'cuisine_preference'
Traceback (most recent call last):
  File "/app/meal_planner/views.py", line 58, in post
    meal_plans = recommender.get_recommendations(user_profile)
  File "/app/meal_planner/ai_model.py", line 297, in get_recommendations
    content_recs = self.content_recommender.get_recommendations(user_profile)
  File "/app/meal_planner/ai_model.py", line 35, in get_recommendations
    f"{' '.join(user_profile['dietary_preferences'])} {user_profile['health_goals']} {user_profile['cuisine_preference']} "
KeyError: 'cuisine_preference'
Internal Server Error: /meals/meal-plans/generate/
Internal Server Error: /recipes/favorites/dR7prO0G/
Traceback (most recent call last):
  File "/usr/local/lib/python3.10/site-packages/django/core/handlers/exception.py", line 55, in inner
    response = get_response(request)
  File "/usr/local/lib/python3.10/site-packages/django/core/handlers/base.py", line 197, in _get_response
    response = wrapped_callback(request, *callback_args, **callback_kwargs)
  File "/usr/local/lib/python3.10/site-packages/django/views/decorators/csrf.py", line 65, in _view_wrapper
    return view_func(request, *args, **kwargs)
  File "/usr/local/lib/python3.10/site-packages/django/views/generic/base.py", line 104, in view
    return self.dispatch(request, *args, **kwargs)
  File "/usr/local/lib/python3.10/site-packages/rest_framework/views.py", line 509, in dispatch
    response = self.handle_exception(exc)
  File "/usr/local/lib/python3.10/site-packages/rest_framework/views.py", line 469, in handle_exception
    self.raise_uncaught_exception(exc)
  File "/usr/local/lib/python3.10/site-packages/rest_framework/views.py", line 480, in raise_uncaught_exception
    raise exc
  File "/usr/local/lib/python3.10/site-packages/rest_framework/views.py", line 506, in dispatch
    response = handler(request, *args, **kwargs)
  File "/app/recipes/views.py", line 207, in post
    data = {'recipe': recipe_id, 'timestamp': timezone.now()}  # Ensure recipe_id and timestamp are in the data
NameError: name 'timezone' is not defined
Internal Server Error: /recipes/favorites/dR7prO0G/
Traceback (most recent call last):
  File "/usr/local/lib/python3.10/site-packages/django/core/handlers/exception.py", line 55, in inner
    response = get_response(request)
  File "/usr/local/lib/python3.10/site-packages/django/core/handlers/base.py", line 197, in _get_response
    response = wrapped_callback(request, *callback_args, **callback_kwargs)
  File "/usr/local/lib/python3.10/site-packages/django/views/decorators/csrf.py", line 65, in _view_wrapper
    return view_func(request, *args, **kwargs)
  File "/usr/local/lib/python3.10/site-packages/django/views/generic/base.py", line 104, in view
    return self.dispatch(request, *args, **kwargs)
  File "/usr/local/lib/python3.10/site-packages/rest_framework/views.py", line 509, in dispatch
    response = self.handle_exception(exc)
  File "/usr/local/lib/python3.10/site-packages/rest_framework/views.py", line 469, in handle_exception
    self.raise_uncaught_exception(exc)
  File "/usr/local/lib/python3.10/site-packages/rest_framework/views.py", line 480, in raise_uncaught_exception
    raise exc
  File "/usr/local/lib/python3.10/site-packages/rest_framework/views.py", line 506, in dispatch
    response = handler(request, *args, **kwargs)
  File "/app/recipes/views.py", line 207, in post
    data = {'recipe': recipe_id, 'timestamp': timezone.now()}  # Ensure recipe_id and timestamp are in the data
NameError: name 'timezone' is not defined
Internal Server Error: /recipes/favorites/dR7prO0G/
Traceback (most recent call last):
  File "/usr/local/lib/python3.10/site-packages/django/core/handlers/exception.py", line 55, in inner
    response = get_response(request)
  File "/usr/local/lib/python3.10/site-packages/django/core/handlers/base.py", line 197, in _get_response
    response = wrapped_callback(request, *callback_args, **callback_kwargs)
  File "/usr/local/lib/python3.10/site-packages/django/views/decorators/csrf.py", line 65, in _view_wrapper
    return view_func(request, *args, **kwargs)
  File "/usr/local/lib/python3.10/site-packages/django/views/generic/base.py", line 104, in view
    return self.dispatch(request, *args, **kwargs)
  File "/usr/local/lib/python3.10/site-packages/rest_framework/views.py", line 509, in dispatch
    response = self.handle_exception(exc)
  File "/usr/local/lib/python3.10/site-packages/rest_framework/views.py", line 469, in handle_exception
    self.raise_uncaught_exception(exc)
  File "/usr/local/lib/python3.10/site-packages/rest_framework/views.py", line 480, in raise_uncaught_exception
    raise exc
  File "/usr/local/lib/python3.10/site-packages/rest_framework/views.py", line 506, in dispatch
    response = handler(request, *args, **kwargs)
  File "/app/recipes/views.py", line 207, in post
    data = {'recipe': recipe_id, 'timestamp': timezone.now()}  # Ensure recipe_id and timestamp are in the data
NameError: name 'timezone' is not defined
Internal Server Error: /recipes/recipes-filter/
Traceback (most recent call last):
  File "/usr/local/lib/python3.10/site-packages/django/core/handlers/exception.py", line 55, in inner
    response = get_response(request)
  File "/usr/local/lib/python3.10/site-packages/django/core/handlers/base.py", line 197, in _get_response
    response = wrapped_callback(request, *callback_args, **callback_kwargs)
  File "/usr/local/lib/python3.10/site-packages/django/views/decorators/csrf.py", line 65, in _view_wrapper
    return view_func(request, *args, **kwargs)
  File "/usr/local/lib/python3.10/site-packages/django/views/generic/base.py", line 104, in view
    return self.dispatch(request, *args, **kwargs)
  File "/usr/local/lib/python3.10/site-packages/rest_framework/views.py", line 509, in dispatch
    response = self.handle_exception(exc)
  File "/usr/local/lib/python3.10/site-packages/rest_framework/views.py", line 469, in handle_exception
    self.raise_uncaught_exception(exc)
  File "/usr/local/lib/python3.10/site-packages/rest_framework/views.py", line 480, in raise_uncaught_exception
    raise exc
  File "/usr/local/lib/python3.10/site-packages/rest_framework/views.py", line 506, in dispatch
    response = handler(request, *args, **kwargs)
  File "/app/recipes/views.py", line 95, in get
    recipes = Recipe.objects.filter(**filters)
  File "/usr/local/lib/python3.10/site-packages/django/db/models/manager.py", line 87, in manager_method
    return getattr(self.get_queryset(), name)(*args, **kwargs)
  File "/usr/local/lib/python3.10/site-packages/django/db/models/query.py", line 1476, in filter
    return self._filter_or_exclude(False, args, kwargs)
  File "/usr/local/lib/python3.10/site-packages/django/db/models/query.py", line 1494, in _filter_or_exclude
    clone._filter_or_exclude_inplace(negate, args, kwargs)
  File "/usr/local/lib/python3.10/site-packages/django/db/models/query.py", line 1501, in _filter_or_exclude_inplace
    self._query.add_q(Q(*args, **kwargs))
  File "/usr/local/lib/python3.10/site-packages/django/db/models/sql/query.py", line 1609, in add_q
    clause, _ = self._add_q(q_object, self.used_aliases)
  File "/usr/local/lib/python3.10/site-packages/django/db/models/sql/query.py", line 1641, in _add_q
    child_clause, needed_inner = self.build_filter(
  File "/usr/local/lib/python3.10/site-packages/django/db/models/sql/query.py", line 1491, in build_filter
    lookups, parts, reffed_expression = self.solve_lookup_type(arg, summarize)
  File "/usr/local/lib/python3.10/site-packages/django/db/models/sql/query.py", line 1303, in solve_lookup_type
    _, field, _, lookup_parts = self.names_to_path(lookup_splitted, self.get_meta())
  File "/usr/local/lib/python3.10/site-packages/django/db/models/sql/query.py", line 1768, in names_to_path
    raise FieldError(
django.core.exceptions.FieldError: Cannot resolve keyword '[object Object]' into field. Choices are: cuisine, dish_type, duration, favorite, gluten_free, halal, image, ingredients, meal_plan_recipes, meal_type, name, nutrition, nutrition_id, pescatarian, rating, recipe_id, recipe_info, tags, vegan, vegetarian
Internal Server Error: /recipes/recipes-filter/
Traceback (most recent call last):
  File "/usr/local/lib/python3.10/site-packages/django/core/handlers/exception.py", line 55, in inner
    response = get_response(request)
  File "/usr/local/lib/python3.10/site-packages/django/core/handlers/base.py", line 197, in _get_response
    response = wrapped_callback(request, *callback_args, **callback_kwargs)
  File "/usr/local/lib/python3.10/site-packages/django/views/decorators/csrf.py", line 65, in _view_wrapper
    return view_func(request, *args, **kwargs)
  File "/usr/local/lib/python3.10/site-packages/django/views/generic/base.py", line 104, in view
    return self.dispatch(request, *args, **kwargs)
  File "/usr/local/lib/python3.10/site-packages/rest_framework/views.py", line 509, in dispatch
    response = self.handle_exception(exc)
  File "/usr/local/lib/python3.10/site-packages/rest_framework/views.py", line 469, in handle_exception
    self.raise_uncaught_exception(exc)
  File "/usr/local/lib/python3.10/site-packages/rest_framework/views.py", line 480, in raise_uncaught_exception
    raise exc
  File "/usr/local/lib/python3.10/site-packages/rest_framework/views.py", line 506, in dispatch
    response = handler(request, *args, **kwargs)
  File "/app/recipes/views.py", line 95, in get
    recipes = Recipe.objects.filter(**filters)
  File "/usr/local/lib/python3.10/site-packages/django/db/models/manager.py", line 87, in manager_method
    return getattr(self.get_queryset(), name)(*args, **kwargs)
  File "/usr/local/lib/python3.10/site-packages/django/db/models/query.py", line 1476, in filter
    return self._filter_or_exclude(False, args, kwargs)
  File "/usr/local/lib/python3.10/site-packages/django/db/models/query.py", line 1494, in _filter_or_exclude
    clone._filter_or_exclude_inplace(negate, args, kwargs)
  File "/usr/local/lib/python3.10/site-packages/django/db/models/query.py", line 1501, in _filter_or_exclude_inplace
    self._query.add_q(Q(*args, **kwargs))
  File "/usr/local/lib/python3.10/site-packages/django/db/models/sql/query.py", line 1609, in add_q
    clause, _ = self._add_q(q_object, self.used_aliases)
  File "/usr/local/lib/python3.10/site-packages/django/db/models/sql/query.py", line 1641, in _add_q
    child_clause, needed_inner = self.build_filter(
  File "/usr/local/lib/python3.10/site-packages/django/db/models/sql/query.py", line 1491, in build_filter
    lookups, parts, reffed_expression = self.solve_lookup_type(arg, summarize)
  File "/usr/local/lib/python3.10/site-packages/django/db/models/sql/query.py", line 1303, in solve_lookup_type
    _, field, _, lookup_parts = self.names_to_path(lookup_splitted, self.get_meta())
  File "/usr/local/lib/python3.10/site-packages/django/db/models/sql/query.py", line 1768, in names_to_path
    raise FieldError(
django.core.exceptions.FieldError: Cannot resolve keyword '[object Object]' into field. Choices are: cuisine, dish_type, duration, favorite, gluten_free, halal, image, ingredients, meal_plan_recipes, meal_type, name, nutrition, nutrition_id, pescatarian, rating, recipe_id, recipe_info, tags, vegan, vegetarian
Internal Server Error: /recipes/recipes-filter/
Traceback (most recent call last):
  File "/usr/local/lib/python3.10/site-packages/django/core/handlers/exception.py", line 55, in inner
    response = get_response(request)
  File "/usr/local/lib/python3.10/site-packages/django/core/handlers/base.py", line 197, in _get_response
    response = wrapped_callback(request, *callback_args, **callback_kwargs)
  File "/usr/local/lib/python3.10/site-packages/django/views/decorators/csrf.py", line 65, in _view_wrapper
    return view_func(request, *args, **kwargs)
  File "/usr/local/lib/python3.10/site-packages/django/views/generic/base.py", line 104, in view
    return self.dispatch(request, *args, **kwargs)
  File "/usr/local/lib/python3.10/site-packages/rest_framework/views.py", line 509, in dispatch
    response = self.handle_exception(exc)
  File "/usr/local/lib/python3.10/site-packages/rest_framework/views.py", line 469, in handle_exception
    self.raise_uncaught_exception(exc)
  File "/usr/local/lib/python3.10/site-packages/rest_framework/views.py", line 480, in raise_uncaught_exception
    raise exc
  File "/usr/local/lib/python3.10/site-packages/rest_framework/views.py", line 506, in dispatch
    response = handler(request, *args, **kwargs)
  File "/app/recipes/views.py", line 95, in get
    recipes = Recipe.objects.filter(**filters)
  File "/usr/local/lib/python3.10/site-packages/django/db/models/manager.py", line 87, in manager_method
    return getattr(self.get_queryset(), name)(*args, **kwargs)
  File "/usr/local/lib/python3.10/site-packages/django/db/models/query.py", line 1476, in filter
    return self._filter_or_exclude(False, args, kwargs)
  File "/usr/local/lib/python3.10/site-packages/django/db/models/query.py", line 1494, in _filter_or_exclude
    clone._filter_or_exclude_inplace(negate, args, kwargs)
  File "/usr/local/lib/python3.10/site-packages/django/db/models/query.py", line 1501, in _filter_or_exclude_inplace
    self._query.add_q(Q(*args, **kwargs))
  File "/usr/local/lib/python3.10/site-packages/django/db/models/sql/query.py", line 1609, in add_q
    clause, _ = self._add_q(q_object, self.used_aliases)
  File "/usr/local/lib/python3.10/site-packages/django/db/models/sql/query.py", line 1641, in _add_q
    child_clause, needed_inner = self.build_filter(
  File "/usr/local/lib/python3.10/site-packages/django/db/models/sql/query.py", line 1491, in build_filter
    lookups, parts, reffed_expression = self.solve_lookup_type(arg, summarize)
  File "/usr/local/lib/python3.10/site-packages/django/db/models/sql/query.py", line 1303, in solve_lookup_type
    _, field, _, lookup_parts = self.names_to_path(lookup_splitted, self.get_meta())
  File "/usr/local/lib/python3.10/site-packages/django/db/models/sql/query.py", line 1768, in names_to_path
    raise FieldError(
django.core.exceptions.FieldError: Cannot resolve keyword '[object Object]' into field. Choices are: cuisine, dish_type, duration, favorite, gluten_free, halal, image, ingredients, meal_plan_recipes, meal_type, name, nutrition, nutrition_id, pescatarian, rating, recipe_id, recipe_info, tags, vegan, vegetarian
